Workbook

Sheet Rawdata
A1: 수험번호 | B1: 이름 | C1: 지원분야 : 1지망 | D1: 지원분야(관리용) | E1: 지원분야 갯수 | F1: 작성일자 | G1: 지원서 제출 | H1: 지원서 제출일자 | I1: 영문이름 | J1: 이메일 | K1: 핸드폰번호 | L1: 긴급연락처 | M1: 장애여부 | N1: 보훈여부 | O1: 병역구분 | P1: 복무시작일 | Q1: 복무종료일 | R1: 제대구분 | S1: 계급 | T1: 연구실적(학술지 게재1) - 게재구분 | U1: 연구실적(학술지 게재1) - 논문구분 | V1: 연구실적(학술지 게재1) - 논문제목 | W1: 연구실적(학술지 게재1) - 게재지명 | X1: 연구실적(학술지 게재1) - 역할 | Y1: 연구실적(학술지 게재1) - 게재일자 | Z1: 연구실적(학술지 게재1) - 저자순위 | AA1: 연구실적(학술지 게재1) - 발행기관 | AB1: 연구실적(학술지 게재1) - ISSN 번호 | AC1: 연구실적(학술지 게재2) - 게재구분 | AD1: 연구실적(학술지 게재2) - 논문구분 | AE1: 연구실적(학술지 게재2) - 논문제목 | AF1: 연구실적(학술지 게재2) - 게재지명 | AG1: 연구실적(학술지 게재2) - 역할 | AH1: 연구실적(학술지 게재2) - 게재일자 | AI1: 연구실적(학술지 게재2) - 저자순위 | AJ1: 연구실적(학술지 게재2) - 발행기관 | AK1: 연구실적(학술지 게재2) - ISSN 번호 | AL1: 연구실적(학술지 게재3) - 게재구분 | AM1: 연구실적(학술지 게재3) - 논문구분 | AN1: 연구실적(학술지 게재3) - 논문제목 | AO1: 연구실적(학술지 게재3) - 게재지명 | AP1: 연구실적(학술지 게재3) - 역할 | AQ1: 연구실적(학술지 게재3) - 게재일자 | AR1: 연구실적(학술지 게재3) - 저자순위 | AS1: 연구실적(학술지 게재3) - 발행기관 | AT1: 연구실적(학술지 게재3) - ISSN 번호 | AU1: 총 경력 | AV1: 경력사항1 - 고용형태 | AW1: 경력사항1 - 회사명 | AX1: 경력사항1 - 재직기간 | AY1: 경력사항1 - 재직기간 시작일 | AZ1: 경력사항1 - 재직기간 종료일 | BA1: 경력사항1 - 부서명 | BB1: 경력사항1 - 직급 | BC1: 경력사항1 - 담당업무 | BD1: 경력사항1 - 퇴직사유 | BE1: 경력사항2 - 고용형태 | BF1: 경력사항2 - 회사명 | BG1: 경력사항2 - 재직기간 | BH1: 경력사항2 - 재직기간 시작일 | BI1: 경력사항2 - 재직기간 종료일 | BJ1: 경력사항2 - 부서명 | BK1: 경력사항2 - 직급 | BL1: 경력사항2 - 담당업무 | BM1: 경력사항2 - 퇴직사유 | BN1: 경력사항3 - 고용형태 | BO1: 경력사항3 - 회사명 | BP1: 경력사항3 - 재직기간 | BQ1: 경력사항3 - 재직기간 시작일 | BR1: 경력사항3 - 재직기간 종료일 | BS1: 경력사항3 - 부서명 | BT1: 경력사항3 - 직급 | BU1: 경력사항3 - 담당업무 | BV1: 경력사항3 - 퇴직사유 | BW1: 경력사항4 - 고용형태 | BX1: 경력사항4 - 회사명 | BY1: 경력사항4 - 재직기간 | BZ1: 경력사항4 - 재직기간 시작일 | CA1: 경력사항4 - 재직기간 종료일 | CB1: 경력사항4 - 부서명 | CC1: 경력사항4 - 직급 | CD1: 경력사항4 - 담당업무 | CE1: 경력사항4 - 퇴직사유 | CF1: 경력사항5 - 고용형태 | CG1: 경력사항5 - 회사명 | CH1: 경력사항5 - 재직기간 | CI1: 경력사항5 - 재직기간 시작일 | CJ1: 경력사항5 - 재직기간 종료일 | CK1: 경력사항5 - 부서명 | CL1: 경력사항5 - 직급 | CM1: 경력사항5 - 담당업무 | CN1: 경력사항5 - 퇴직사유 | CO1: 시험명 | CP1: 공인 외국어시험 - G-TELP 취득등급(점수) | CQ1: 공인 외국어시험 - G-TELP 응시일 | CR1: 공인 외국어시험 - G-TELP 등록번호 | CS1: 시험명 | CT1: 공인 외국어시험 - TEPS 취득등급(점수) | CU1: 공인 외국어시험 - TEPS 응시일 | CV1: 공인 외국어시험 - TEPS 등록번호 | CW1: 시험명 | CX1: 공인 외국어시험 - TOEFL 취득등급(점수) | CY1: 공인 외국어시험 - TOEFL 응시일 | CZ1: 공인 외국어시험 - TOEFL 등록번호 | DA1: 시험명 | DB1: 공인 외국어시험 - TOEFL(IBT) 취득등급(점수) | DC1: 공인 외국어시험 - TOEFL(IBT) 응시일 | DD1: 공인 외국어시험 - TOEFL(IBT) 등록번호 | DE1: 시험명 | DF1: 공인 외국어시험 - TOEIC 취득등급(점수) | DG1: 공인 외국어시험 - TOEIC 응시일 | DH1: 공인 외국어시험 - TOEIC 등록번호 | DI1: 시험명 | DJ1: 공인 외국어시험 - Toeic Speaking test 취득등급(점수) | DK1: 공인 외국어시험 - Toeic Speaking test 응시일 | DL1: 공인 외국어시험 - Toeic Speaking test 등록번호 | DM1: 시험명 | DN1: 공인 외국어시험 - 신HSK(PBT) 취득등급(점수) | DO1: 공인 외국어시험 - 신HSK(PBT) 응시일 | DP1: 공인 외국어시험 - 신HSK(PBT) 등록번호 | DQ1: 시험명 | DR1: 공인 외국어시험 - OPIc(중국어) 취득등급(점수) | DS1: 공인 외국어시험 - OPIc(중국어) 응시일 | DT1: 공인 외국어시험 - OPIc(중국어) 등록번호 | DU1: 시험명 | DV1: 공인 외국어시험 - IELTS 취득등급(점수) | DW1: 공인 외국어시험 - IELTS 응시일 | DX1: 공인 외국어시험 - IELTS 등록번호 | DY1: 시험명 | DZ1: 공인 외국어시험 - OPIc(영어) 취득등급(점수) | EA1: 공인 외국어시험 - OPIc(영어) 응시일 | EB1: 공인 외국어시험 - OPIc(영어) 등록번호 | EC1: 시험명 | ED1: 공인 외국어시험 - 신HSK(IBT) 취득등급(점수) | EE1: 공인 외국어시험 - 신HSK(IBT) 응시일 | EF1: 공인 외국어시험 - 신HSK(IBT) 등록번호 | EG1: 시험명 | EH1: 공인 외국어시험 - G-telp(Level 2) 취득등급(점수) | EI1: 공인 외국어시험 - G-telp(Level 2) 응시일 | EJ1: 공인 외국어시험 - G-telp(Level 2) 등록번호 | EK1: 시험명 | EL1: 공인 외국어시험 - TOEIC(2년이상 직접등록) 취득등급(점수) | EM1: 공인 외국어시험 - TOEIC(2년이상 직접등록) 응시일 | EN1: 공인 외국어시험 - TOEIC(2년이상 직접등록) 등록번호 | EO1: 시험명 | EP1: 공인 외국어시험 - Toeic Speaking test(2년이상 직접등록) 취득등급(점수) | EQ1: 공인 외국어시험 - Toeic Speaking test(2년이상 직접등록) 응시일 | ER1: 공인 외국어시험 - Toeic Speaking test(2년이상 직접등록) 등록번호 | ES1: 시험명 | ET1: 공인 외국어시험 - OPIc(영어) - 2년이상 직접등록 취득등급(점수) | EU1: 공인 외국어시험 - OPIc(영어) - 2년이상 직접등록 응시일 | EV1: 공인 외국어시험 - OPIc(영어) - 2년이상 직접등록 등록번호 | EW1: 시험명 | EX1: 공인 외국어시험 - G-TELP(2년이상 직접등록) 취득등급(점수) | EY1: 공인 외국어시험 - G-TELP(2년이상 직접등록) 응시일 | EZ1: 공인 외국어시험 - G-TELP(2년이상 직접등록) 등록번호 | FA1: 시험명 | FB1: 공인 외국어시험 - G-TELP Speaking (GST)(2년이상 직접등록) 취득등급(점수) | FC1: 공인 외국어시험 - G-TELP Speaking (GST)(2년이상 직접등록) 응시일 | FD1: 공인 외국어시험 - G-TELP Speaking (GST)(2년이상 직접등록) 등록번호 | FE1: 시험명 | FF1: 공인 외국어시험 - NEW TEPS 취득등급(점수) | FG1: 공인 외국어시험 - NEW TEPS 응시일 | FH1: 공인 외국어시험 - NEW TEPS 등록번호 | FI1: 총 자격증 개수 | FJ1: 자격증1 - 명칭 | FK1: 자격증1 - 발급기관 | FL1: 자격증1 - 등록번호 | FM1: 자격증1 - 취득일 | FN1: 자격증2 - 명칭 | FO1: 자격증2 - 발급기관 | FP1: 자격증2 - 등록번호 | FQ1: 자격증2 - 취득일 | FR1: NCS 교육사항(학교) - 능력단위별 총 이수학점 | FS1: NCS 교육사항(학교)1 - 과목명 | FT1: NCS 교육사항(학교)1 - 능력단위 | FU1: NCS 교육사항(학교)1 - 이수기간 | FV1: NCS 교육사항(학교)1 - 이수기간 시작일 | FW1: NCS 교육사항(학교)1 - 이수기간 종료일 | FX1: NCS 교육사항(학교)1 - 주요내용 | FY1: NCS 교육사항(학교)1 - 이수학점(학점) | FZ1: NCS 교육사항(학교)1 - 취득성적 | GA1: NCS 교육사항(학교)1 - 만점 | GB1: NCS 교육사항(학교)2 - 과목명 | GC1: NCS 교육사항(학교)2 - 능력단위 | GD1: NCS 교육사항(학교)2 - 이수기간 | GE1: NCS 교육사항(학교)2 - 이수기간 시작일 | GF1: NCS 교육사항(학교)2 - 이수기간 종료일 | GG1: NCS 교육사항(학교)2 - 주요내용 | GH1: NCS 교육사항(학교)2 - 이수학점(학점) | GI1: NCS 교육사항(학교)2 - 취득성적 | GJ1: NCS 교육사항(학교)2 - 만점 | GK1: NCS 교육사항(학교)3 - 과목명 | GL1: NCS 교육사항(학교)3 - 능력단위 | GM1: NCS 교육사항(학교)3 - 이수기간 | GN1: NCS 교육사항(학교)3 - 이수기간 시작일 | GO1: NCS 교육사항(학교)3 - 이수기간 종료일 | GP1: NCS 교육사항(학교)3 - 주요내용 | GQ1: NCS 교육사항(학교)3 - 이수학점(학점) | GR1: NCS 교육사항(학교)3 - 취득성적 | GS1: NCS 교육사항(학교)3 - 만점 | GT1: NCS 교육사항(학교)4 - 과목명 | GU1: NCS 교육사항(학교)4 - 능력단위 | GV1: NCS 교육사항(학교)4 - 이수기간 | GW1: NCS 교육사항(학교)4 - 이수기간 시작일 | GX1: NCS 교육사항(학교)4 - 이수기간 종료일 | GY1: NCS 교육사항(학교)4 - 주요내용 | GZ1: NCS 교육사항(학교)4 - 이수학점(학점) | HA1: NCS 교육사항(학교)4 - 취득성적 | HB1: NCS 교육사항(학교)4 - 만점 | HC1: NCS 교육사항(학교)5 - 과목명 | HD1: NCS 교육사항(학교)5 - 능력단위 | HE1: NCS 교육사항(학교)5 - 이수기간 | HF1: NCS 교육사항(학교)5 - 이수기간 시작일 | HG1: NCS 교육사항(학교)5 - 이수기간 종료일 | HH1: NCS 교육사항(학교)5 - 주요내용 | HI1: NCS 교육사항(학교)5 - 이수학점(학점) | HJ1: NCS 교육사항(학교)5 - 취득성적 | HK1: NCS 교육사항(학교)5 - 만점 | HL1: NCS 교육사항(직업) - 능력단위별 총 교육시간 | HM1: NCS 교육사항(직업)1 - 과정명 | HN1: NCS 교육사항(직업)1 - 능력단위 | HO1: NCS 교육사항(직업)1 - 개별교육시간 | HP1: NCS 교육사항(직업)1 - 이수기간 | HQ1: NCS 교육사항(직업)1 - 이수기간 시작일 | HR1: NCS 교육사항(직업)1 - 이수기간 종료일 | HS1: NCS 교육사항(직업)1 - 주요내용 | HT1: NCS 교육사항(직업)1 - 교육기관명 | HU1: NCS 교육사항(직업)2 - 과정명 | HV1: NCS 교육사항(직업)2 - 능력단위 | HW1: NCS 교육사항(직업)2 - 개별교육시간 | HX1: NCS 교육사항(직업)2 - 이수기간 | HY1: NCS 교육사항(직업)2 - 이수기간 시작일 | HZ1: NCS 교육사항(직업)2 - 이수기간 종료일 | IA1: NCS 교육사항(직업)2 - 주요내용 | IB1: NCS 교육사항(직업)2 - 교육기관명 | IC1: NCS 교육사항(직업)3 - 과정명 | ID1: NCS 교육사항(직업)3 - 능력단위 | IE1: NCS 교육사항(직업)3 - 개별교육시간 | IF1: NCS 교육사항(직업)3 - 이수기간 | IG1: NCS 교육사항(직업)3 - 이수기간 시작일 | IH1: NCS 교육사항(직업)3 - 이수기간 종료일 | II1: NCS 교육사항(직업)3 - 주요내용 | IJ1: NCS 교육사항(직업)3 - 교육기관명 | IK1: NCS 교육사항(직업)4 - 과정명 | IL1: NCS 교육사항(직업)4 - 능력단위 | IM1: NCS 교육사항(직업)4 - 개별교육시간 | IN1: NCS 교육사항(직업)4 - 이수기간 | IO1: NCS 교육사항(직업)4 - 이수기간 시작일 | IP1: NCS 교육사항(직업)4 - 이수기간 종료일 | IQ1: NCS 교육사항(직업)4 - 주요내용 | IR1: NCS 교육사항(직업)4 - 교육기관명 | IS1: NCS 교육사항(직업)5 - 과정명 | IT1: NCS 교육사항(직업)5 - 능력단위 | IU1: NCS 교육사항(직업)5 - 개별교육시간 | IV1: NCS 교육사항(직업)5 - 이수기간 | IW1: NCS 교육사항(직업)5 - 이수기간 시작일 | IX1: NCS 교육사항(직업)5 - 이수기간 종료일 | IY1: NCS 교육사항(직업)5 - 주요내용 | IZ1: NCS 교육사항(직업)5 - 교육기관명 | JA1: NCS 교육사항(직업) - 총 교육시간 | JB1: 자기소개서 1번 | JC1: 자기소개서 2번 | JD1: 자기소개서 3번 | JE1: 자기소개서 4번 | JF1: 부가정보_1 : 생월일(ex.0725) | JG1: 인적사항_1 : 저소득층 해당 여부 | JH1: 인적사항_2 : 한부모가족 해당 여부 | JI1: 인적사항_3 : 자립준비청년 해당 여부 | JJ1: 인적사항_4 : 북한이탈주민 해당 여부 | JK1: 인적사항_5 : 다문화가정 해당 여부 | JL1: 인적사항_6 : 비수도권지역인재 해당 여부 | JM1: 인적사항_7 : 이전지역인재 해당 여부 | JN1: 인적사항_8 : 공공기관 청년 인턴(5개월 이상인 자) 경험자 해당 여부 | JO1: 인적사항_9 : [청년고용촉진 특별법]에 따른 청년 해당 여부 | JP1: 인적사항_10 : 경력단절여성 해당 여부 | JQ1: 자기소개서_1 : 지원한 직무에 대해 ①본인이 이해하고 있는 내용과 ②그 직무 수행에 필요하다고 생각하는 역량은 무엇이며 ③어떠한 노력으로 그 역량들을 갖추게 되었는지 또는 갖출 것인지 작성해 주시기 바랍니다. 또한 해당 역량을 실제로 적용하여 성과를 창출했거나 문제 해결에 활용한 경험이 있다면 함께 기술하여 주시기 바랍니다. | JR1: 자기소개서_2 : 한국보건산업진흥원의 역할과 조직 가치에 대해 본인이 이해하고 있는 내용을 설명하고, 입사 후 이러한 가치를 지키며 업무를 수행하기 위해 필요한 직업윤리는 무엇인지, 그 직업 윤리를 갖추기 위해 했던 노력이나 앞으로의 계획을 작성해 주시기 바랍니다. | JS1: 자기소개서_3 : 집단 또는 조직 생활에서 구성원 간의 갈등이나 협업의 어려움 등 문제 상황을 겪은 경험이 있다면 기술하여 주시기 바랍니다. 해당 상황에서 본인이 주도적으로 문제를 해결한 과정과 결과, 그리고 본인의 역할에 대해 구체적으로 작성해 주시기 바랍니다. | JT1: 자기소개서_4 : 본인이 가진 강점 중 진흥원 입사 후 더욱 발전적으로 성장할 수 있는 요소가 있다면 그 강점은 무엇인지, 왜 그렇게 생각하는지 진흥원의 조직문화나 업무환경과 연계하여 작성해 주시기 바랍니다. 또한 본인이 생각하는 보완해야 할 약점이 있다면 그 약점은 무엇인지, 왜 그렇게 생각하는지 함께 기술하여 주시기 바랍니다.
A2: 0005-000011 | B2: 최지호 | C2: 1지망 : 보건산업진흥지원-정규직-전문직/연구원-오송 | D2: 03_보건산업진흥지원-정규직-전문직/연구원-오송 | E2: 1 | F2: 2025.07.18 | G2: 제출완료 | H2: 2025.07.31 | I2: Choi Jiho | J2: okcjhh@naver.com | K2: 010-3059-2886 | L2: 010-7243-2886 | M2: 해당없음 | N2: 해당없음 | O2: 비대상 | P2: - | Q2: - | R2: - | S2: - | T2: - | U2: - | V2: - | W2: - | X2: - | Y2: - | Z2: - | AA2: - | AB2: - | AC2: - | AD2: - | AE2: - | AF2: - | AG2: - | AH2: - | AI2: - | AJ2: - | AK2: - | AL2: - | AM2: - | AN2: - | AO2: - | AP2: - | AQ2: - | AR2: - | AS2: - | AT2: - | AU2: 1년9개월 | AV2: 계약직 | AW2: 한국보건산업진흥원 | AX2: 1개월 | AY2: 2025.07.01 | AZ2: 재직중 | BA2: 제약바이오산업단 | BB2: 연구원(기간제) | BC2: K-블록버스터 글로벌 진출 지원 | BD2: 재직중 | BE2: 계약직 | BF2: 한국보건산업진흥원 | BG2: 8개월 | BH2: 2024.11.01 | BI2: 2025.06.30 | BJ2: 외국인환자유치단 | BK2: 연구원(기간제) | BL2: 소셜미디어 활용 한국의료 글로벌 홍보, Medical Korea 2025 콘퍼런스 홍보 | BM2: 계약만료 | BN2: 공공기관 청년인턴(체험형,채용형) | BO2: 한국보건산업진흥원 | BP2: 6개월 | BQ2: 2024.04.01 | BR2: 2024.09.30 | BS2: 의료기술RnD단 | BT2: 인턴 | BU2: 질병관리청 기획용역 관리 | BV2: 계약만료 | BW2: 공공기관 청년인턴(체험형,채용형) | BX2: 한국보건복지인재원 | BY2: 4개월 | BZ2: 2020.09.21 | CA2: 2021.01.20 | CB2: 정보화전략부 | CC2: 인턴 | CD2: 부서 Cop, 청렴, 영상시스템 계정 대여, 정보화사업·정보보안·정보시스템 등의 행정업무지원 | CE2: 계약만료 | CF2: 공공기관 청년인턴(체험형,채용형) | CG2: 한국전자통신연구원 | CH2: 2개월 | CI2: 2020.07.01 | CJ2: 2020.08.31 | CK2: 지능화정책연구실 | CL2: 인턴 | CM2: 국내외 주요 통신사 5G 시장 서비스 동향 정보수집 및 분석 | CN2: 계약만료 | CO2: - | CP2: - | CQ2: - | CR2: - | CS2: - | CT2: - | CU2: - | CV2: - | CW2: - | CX2: - | CY2: - | CZ2: - | DA2: - | DB2: - | DC2: - | DD2: - | DE2: - | DF2: - | DG2: - | DH2: - | DI2: Toeic Speaking test | DJ2: Intermediate High | DK2: 2023.11.12 | DL2: 102017 | DM2: - | DN2: - | DO2: - | DP2: - | DQ2: - | DR2: - | DS2: - | DT2: - | DU2: - | DV2: - | DW2: - | DX2: - | DY2: - | DZ2: - | EA2: - | EB2: - | EC2: - | ED2: - | EE2: - | EF2: - | EG2: - | EH2: - | EI2: - | EJ2: - | EK2: - | EL2: - | EM2: - | EN2: - | EO2: - | EP2: - | EQ2: - | ER2: - | ES2: - | ET2: - | EU2: - | EV2: - | EW2: - | EX2: - | EY2: - | EZ2: - | FA2: - | FB2: - | FC2: - | FD2: - | FE2: - | FF2: - | FG2: - | FH2: - | FI2: 2 | FJ2: 컴퓨터활용능력1급 | FK2: 대한상공회의소 | FL2: 20-K9-053724 | FM2: 2020.07.03 | FN2: 한국사능력검정시험(1급) | FO2: 국사편찬위원회 | FP2: 45-124778 | FQ2: 2019.11.08 | FR2: 보건산업진흥지원 - 15학점 | FS2: 공공 데이터사이언스의 이해 | FT2: 보건산업진흥지원 | FU2: - | FV2: - | FW2: - | FX2: 공공기관의 이슈를 다루고 R과 Tableau를 이용해 데이터를 분석하고 시각화함 | FY2: 3 | FZ2: - | GA2: - | GB2: 공공 서비스 및 정책 분석 프로젝트 | GC2: 보건산업진흥지원 | GD2: - | GE2: - | GF2: - | GG2: 공공서비스와 정책 기획·분석 전 과정을 실습하며, 실제 통계처리 및 데이터 분석을 통해 정책대안 도출 과정을 경험함 | GH2: 3 | GI2: - | GJ2: - | GK2: 프로젝트 관리 | GL2: 보건산업진흥지원 | GM2: - | GN2: - | GO2: - | GP2: 과업 분담, 일정 조정, 리스크 대응 등 프로젝트 수행 전반의 관리 기법을 실습을 통해 익힘 | GQ2: 3 | GR2: - | GS2: - | GT2: 경영정보시스템 | GU2: 보건산업진흥지원 | GV2: - | GW2: - | GX2: - | GY2: 경영환경, 정보기술의 전략적 응용, 정보기술과 조직구조 및 조직문화, 정보시스템의 전략적 계획 등에 대해 학습함 | GZ2: 3 | HA2: - | HB2: - | HC2: 비즈니스 커뮤니케이션 실무 | HD2: 보건산업진흥지원 | HE2: - | HF2: - | HG2: - | HH2: 비즈니스 프레젠테이션 역량 강화를 위해 최근 이슈를 주제로 하여 그 내용을 영어로 발표함 | HI2: 3 | HJ2: - | HK2: - | HL2: - | HM2: - | HN2: - | HO2: - | HP2: - | HQ2: - | HR2: - | HS2: - | HT2: - | HU2: - | HV2: - | HW2: - | HX2: - | HY2: - | HZ2: - | IA2: - | IB2: - | IC2: - | ID2: - | IE2: - | IF2: - | IG2: - | IH2: - | II2: - | IJ2: - | IK2: - | IL2: - | IM2: - | IN2: - | IO2: - | IP2: - | IQ2: - | IR2: - | IS2: - | IT2: - | IU2: - | IV2: - | IW2: - | IX2: - | IY2: - | IZ2: - | JA2: - | JB2: 1451 | JC2: 1499 | JD2: 1500 | JE2: 1415 | JF2: 0703 | JG2: 비해당 | JH2: 비해당 | JI2: 비해당 | JJ2: 비해당 | JK2: 비해당 | JL2: 해당(충북) | JM2: 해당(충북) | JN2: 해당 | JO2: 해당 | JP2: 비해당 | JQ2: [ 기획력과 분석력 :: 실무 경험을 통해 갖춘 역량 ] 보건산업진흥지원 직무는 보건산업 분야(제약바이오, 의료기기 등)의 기술사업화, 창업지원, 정책수립, 해외진출, 인재양성 등 경쟁력 제고를 위해 체계적으로 운영하며 성과를 관리해 나가는 역할이라고 생각합니다. 이를 위해서는 산업의 동향을 파악할 수 있는 분석력과 이를 실무로 연결할 수 있는 기획력이 필요하다고 생각합니다. 저는 이 두 역량을 갖추기 위해 다음과 같은 경험을 쌓았습니다. 첫째, 기획력입니다. 한국보건산업진흥원에서 '소셜미디어 활용 한국의료 글로벌 홍보' 사업의 전 과정을 경험했습니다. 시행계획을 작성하며 연간 운영 방향을 마련했고, 사업계획서와 실행예산서를 통해 사업 구조와 예산을 직접 배분해 보았습니다. 선정평가를 통해 수행기관을 선정한 후에는 실적 관리, 보고서 작성, 대응자료 작성 등 실무 전반을 맡았습니다. 그리고 한국의료를 알리기 위해 콘텐츠 기획, 출연자 섭외, 콘텐츠 검수까지 실질적인 사업을 수행했습니다. 정부부처, 병원, 수행기관 등 다양한 이해관계자들과 협업하면서 여러 사람과 소통하는 방법과 일정을 조율하는 방법을 배울 수 있었습니다. 그리고 사업 종료 후에는 조직성과 및 실적보고서 작성까지 사업을 책임감 있게 마무리했습니다. 사업 보조가 아닌 기획부터 실행, 평가까지 한 사이클을 경험해 보면서 사업을 주도적으로 이끌 수 있는 역량을 길렀습니다. 그 결과, 한국의료에 대한 전문성 있는 이미지를 구축할 수 있었고, 노출되면 바로 볼 수 있는 숏폼을 확대하여 본편 시청 시간 대비 15배 이상 높아 더 많은 외국인환자들에게 도달할 수 있었습니다. 특히, SNS 총구독자 수는 10만 명을 돌파하는 성과를 달성했습니다. 둘째, 분석력입니다. 한국전자통신연구원에서 인턴으로 근무하며 단순 정보 수집 업무를 맡았습니다. 그러나 이에 그치지 않고 수집한 데이터를 바탕으로 엑셀과 Tableau로 분석했습니다. 그 결과, 5G에 대한 호의적인 감정에도 불구하고 가입자 수가 늘어나지 않는 유의미한 결론을 도출해 냈습니다. 이 연구 과제를 더욱 풍부하게 작성하기 위해 자발적으로 본부 내 세미나에 참석하여 여러 자문도 구해봤습니다. 그 결과, 앞으로의 국내 5G 서비스 시장은 월드가든 형태의 폐쇄성 서비스 대신 개방성을 택해 모든 이용자에게 개방하는 전략을 내세워야 한다고 방향성을 제시하는 보고서를 작성했습니다. 실제 현업 종사자들과도 논의를 통해 분석 결과를 더욱 현실적이고 구체적으로 제안할 수 있었습니다. 이 과정에서 문제 정의, 데이터 정제, 시각화, 결론 도출 등 전 과정을 수행하며 분석을 통해 해결책을 제시할 수 있다는 것을 깨달았습니다. 향후에는 이런 실무 경험을 바탕으로 기획력을 좀 더 발전시키고 싶습니다. 분석력을 기반으로 산업의 동향을 파악하여 보건산업 지원사업의 정책 및 전략 개발, 종합계획 수립 등 보건산업 전반을 아우르는 거시적인 업무를 수행해 보고 싶습니다. | JR2: [ 책임감 :: 보건 산업의 발전을 위한 3가지 노력 ] 한국보건산업진흥원의 역할은 보건산업 육성과 국제 경쟁력 제고로 국민 삶의 질을 향상시키는 역할을 하고 있습니다. 기술사업화, 제약바이오, 의료기기, 인재양성 등 보건산업 분야의 사업을 발굴하고 활성화하기 위해 다양한 노력을 해오고 있습니다. 진흥원은 전문성과 신뢰를 기반으로 정부부처, 기업 등 다양한 이해관계자들과의 소통을 통해 도전적인 사업들을 실현해 나가고 있습니다. 이를 위해 필요한 직업윤리는 책임감이라고 생각합니다. 진흥원이 수행하는 사업은 국가의 보건의료체계를 강화하고, 국민의 생명과 건강에 직접적인 영향을 미치기 때문입니다. 저는 책임감을 갖추기 위해 3가지의 노력을 했습니다. 첫째, 진흥원 기간제로 근무하며, 'Medical Korea 2025' 홍보 총괄을 맡아 주인의식을 가지고 업무를 수행했습니다. 행사를 준비하며 복지부-진흥원-PCO와의 협업 속에서 예산, 품질, 일정 등을 고려하며 홍보 전략을 수립했습니다. 옥외전광판, KTX 열차 광고 등 매체 선정 시 타겟 효과성과 메시지 전달력을 고려했고, 카드뉴스·뉴스레터와 같은 콘텐츠들은 대중성을 고려해 표현 하나에도 신중히 처리했습니다. 블로그 인플루언서 섭외와 관련 학과 학생 참여도 제안하며 참여층을 확대했습니다. 행사의 전반적인 내용을 담은 현장 브로슈어는 정보가 한눈에 들어올 수 있도록 직관적으로 구성했습니다. 그 결과, 2024년 참석자 수 4,460명 대비 약 43% 증가라는 성과를 달성했습니다. 둘째, 진흥원 인턴으로 근무하며, 질병관리청 RnD사업 기획연구 관리 업무를 맡아 연구자들의 행정 부담을 줄이고자 노력했습니다. 7개의 기획 용역을 관리하면서 기술평가, 일정 관리, 착수계 검토, 참여 연구원 변경 등 반복적인 행정 업무를 책임감 있게 수행했습니다. 특히, 누락 방지를 위해 서류 점검표를 제작해 서명 하나까지도 꼼꼼하게 체크했습니다. 그리고 업무의 공백이 생기지 않도록 인수인계 파일을 작성하고 자주 받는 질문은 FAQ 형식으로 정리해 대응력을 높였습니다. 그 결과, 박테리오파지, 만성감염코호트 등 핵심 분야의 기획연구가 원활히 추진되는데 기여하였습니다. 셋째, 진흥원 기간제로 근무하며, 팀 주무 맡아 업무의 효율을 높이기 위한 개선을 시도했습니다. 팀에 업무를 전달할 때, 좀 더 효율적으로 확인할 수 있도록 단순히 복사-붙여넣기를 하는 것이 아닌 팀에게 필요한 핵심 정보를 미리 정리해 팀원들이 내용 파악 시간을 줄이고자 했습니다. 첨부파일 확인 전 확인해야 할 부분 언급, 셀 색상 구분, 네모 박스 표시, 엑셀 필터 등을 통해 가독성을 높이고자 했습니다. 그 결과, 팀원들이 업무의 흐름을 빠르게 파악할 수 있고 전달력이 높아졌다는 평가를 받았습니다. 입사 후, 보건산업 분야의 기술사업화나 기술이전 등의 업무를 책임감 있게 수행하고 싶습니다. 우리나라의 우수한 보건의료 기술이 더 많은 기회가 닿을 수 있도록 시장 환경을 조성하고, 국내 기업이 글로벌 경쟁력을 갖출 수 있도록 노력하겠습니다. | JS2: [ 번역 가이드라인 :: 제작 기간 단축과 콘텐츠 완성도 제고 ] 한국보건산업진흥원 기간제로 근무하며, 반복되는 번역 오류로 인한 갈등을 주도적으로 해결한 경험이 있습니다. 번역 가이드라인을 만들고 소통 방식의 개선을 통해 일정을 지키면서도 완성도를 높이는 결과를 이끌었습니다. 그리고 이해관계자 간 조율과 기획 과정 전반을 이끌며 문제 해결 역량을 길렀습니다. '소셜미디어 활용 한국의료 글로벌 홍보' 사업을 맡아 중증질환과 한국의료의 우수성을 알리는 카드뉴스를 제작하였습니다. 그러나 번역 과정에서 반복적인 오류가 발생했고, 일부 콘텐츠는 공식 의학 용어가 아닌 비공식 표현으로 번역한 것을 발견했습니다. 일부 콘텐츠는 한국의료를 오해하게 만들 수 있는 표현도 있었습니다. 처음에는 단순한 품질 이슈로 여기고 수정 요청을 했지만, 시간이 지날수록 기획보다 번역 오류를 해결하는 데 더 많은 시간을 보내고 있다는 것을 인식하게 되었습니다. 어떤 콘텐츠는 일정이 2배 이상 지연되기도 하였는데 이러한 상황이 반복되며 수행기관의 담당자와 갈등이 발생했습니다. 그 과정에서 콘텐츠 담당자와 번역 담당자 간에 책임을 두고 불편한 분위기가 형성되는 상황까지 이어졌습니다. 저는 갈등의 원인이 개인의 실수가 아닌 의료 분야에 대한 전문성 부족과 가이드라인 부재 속에 있다고 생각했습니다. 질환명이나 한국의료 현황 문구는 잘못 번역되면 신뢰도 차원에서 영향을 줄 수 있는 부분이기 때문에 구체적인 가이드라인이 필요하다고 판단했습니다. 단순히 수정만 요청하는 것이 아니라 오류를 방지할 수 있는 구조를 갖추는 것이 우선이라고 생각했습니다. 이에 저는 세 가지의 해결 방안을 마련했습니다. 첫째, 번역 가이드라인을 마련했습니다. 의학 용어와 관련 표현의 오류를 줄이기 위해 반드시 공식적 의학 용어를 사용할 것을 명시했습니다. 질환명이나 보건의료 관련 문구는 WHO, NIH 등 공신력 있는 기관의 용례를 참고할 수 있도록 했습니다. 중국어나 러시아어처럼 문화적 차이가 큰 언어는 현지 검색 엔진과 포털을 통해 자연스러운 표현을 반영하도록 했습니다. 둘째, 검수 과정에서 소통 방식을 개선했습니다. 기존에는 잘못된 번역 문장에 대한 수정 요청만 요구했지만, 이후에는 번역 의도와 문맥을 함께 확인하는 방식으로 전환해 오류 가능성을 줄여나갔습니다. 담당자 간 피드백도 정리된 양식으로 주고받으며 수정횟수와 소요 시간을 절반 이상으로 줄일 수 있었습니다. 셋째, 일정 안정화를 위한 사전 협의와 일정 조율을 강화했습니다. 콘텐츠 제작 초기 단계부터 번역 담당자와 일정 공유를 시작했습니다. 시안 전달 일정도 1~2일 앞당겨 의견을 반영할 수 있는 여유시간을 확보해 제작 일정이 안정적으로 유지될 수 있었습니다. 그 결과, 제작일정이 안정화되고 콘텐츠의 질에 집중할 수 있게 되었습니다. 수행기관 측에서도 가이드라인이 생겨 작업 효율이 높아졌다는 반응을 보였습니다. 앞으로도 갈등이 생기면 원인을 분석하고, 가이드라인을 마련하여 정확하고 일관성 있는 태도로 문제를 해결해 나가겠습니다. | JT2: [ 사전대응력과 창의력 보완 :: 보건산업분야 기획 역량의 확장 ] 저의 강점은 '사전대응력'이 높다는 점입니다. 업무의 구조를 빠르게 파악하고, 발생할 수 있는 문제들을 사전에 대비하고 발견하여 업무를 안정적으로 이끌어 나갈 수 있습니다. 실제로 'K-블록버스터 글로벌 진출 지원' 사업을 수행하며, 행사장 임차 계약서를 검토하던 중 내부 계획안과 임차 시간대가 맞지 않는 것을 발견했습니다. 아직 국내 참가 기업에는 공지가 나가기 전이었고, 사수 선생님과 팀장님 모두 해당 오류를 인지하지 못한 상황이었습니다. 발견한 즉시 빠르게 보고하여 수정안을 반영하였고, 혼선이 생기기 전에 조율을 마칠 수 있었습니다. 만약 이 문제가 행사를 앞두고 발견되었다면 공지 변경과 일정 재조율로 큰 혼란이 발생했을 것입니다. 그러나 사전에 발견한 덕분에 일정 지연이나 책임 소재 갈등 없이 안정적으로 진행될 수 있었습니다. 이러한 강점은 진흥원의 업무환경과도 매우 연관성이 있다고 생각합니다. 다양한 이해관계자와 협업하고, 글로벌 네트워크 속에서 일정을 조율해야 하는 상황이 많기 때문입니다. 따라서 사전에 발생할 수 있는 문제를 발견하고 유연하게 대처하는 모습은 업무의 정확성과 신뢰 확보에 도움이 될 것입니다. 특히, 기술사업화, 기술이전, 제약바이오 및 의료기기산업 해외진출 등은 계약, 평가, 홍보 등 여러 흐름을 동시에 파악해야 하므로 사전대응력이 더욱 중요하다고 생각합니다. 저는 이러한 강점을 바탕으로 복잡한 환경에서도 중심을 잡고 업무를 수행할 것입니다. 반면, 저의 약점은 창의력이 다소 부족하다는 점입니다. 완전히 새로운 백지에서 결과물을 만들어야 하는 상황에서는 무엇부터 시작해야 할지 막막함을 느끼는 편이지만, 분석력과 대인관계 역량을 통해 극복해 나가고 있습니다. '소셜미디어 활용 한국의료 글로벌 홍보' 사업의 발주를 준비하며, 기존 콘텐츠와의 차별성을 고민하게 되었습니다. 그 과정에서 쉽게 방향을 잡지 못해 상급자의 의견을 경청하여 조언을 얻은 뒤, 현지 환우회와의 연계라는 실질적인 접근을 아이디어로 발전시켜 반영했습니다. 또한, 자료조사를 통해 중증질환과 더불어 경증질환까지 콘텐츠의 범위를 확장할 수 있도록 계획하였습니다. 이처럼 약점을 분석력과 대인관계 역량으로 보완하고 있습니다. 창의적인 접근이 필요할 때에는 핵심을 파악하여 다양한 정보와 사람들 의견을 듣고 현실적인 기획으로 발전시키는 전략을 세우고 있습니다. 입사 후에도 사전대응력과 분석력, 대인관계 역량을 통해 실무 경험을 쌓아 보건산업 전반을 아우르는 전략적인 기획을 세워보고 싶습니다. 보건산업의 해외 진출과 기술이전의 기반이 되는 기획과 홍보 업무를 맡게 된다면 저의 강점은 더욱 발전시키고, 약점은 보완해 나갈 수 있을 것입니다. 유연하게 대응하고 실행력을 바탕으로 보건산업의 글로벌 진출을 위해 끊임없이 성장해 나가겠습니다.
A3: 0005-000012 | B3: 곽자영 | C3: 1지망 : 국제의료사업지원-정규직(전임)-전문직/연구원-오송 | D3: 04_국제의료사업지원-정규직(전임)-전문직/연구원-오송 | E3: 1 | F3: 2025.07.18 | G3: 제출완료 | H3: 2025.07.31 | I3: Kwak Jayoung | J3: wkdud0775@naver.com | K3: 010-9698-0423 | L3: 010-8622-0139 | M3: 해당없음 | N3: 해당없음 | O3: 비대상 | P3: - | Q3: - | R3: - | S3: - | T3: - | U3: - | V3: - | W3: - | X3: - | Y3: - | Z3: - | AA3: - | AB3: - | AC3: - | AD3: - | AE3: - | AF3: - | AG3: - | AH3: - | AI3: - | AJ3: - | AK3: - | AL3: - | AM3: - | AN3: - | AO3: - | AP3: - | AQ3: - | AR3: - | AS3: - | AT3: - | AU3: 1년4개월 | AV3: 계약직 | AW3: 한국보건산업진흥원 | AX3: 1개월 | AY3: 2025.07.01 | AZ3: 재직중 | BA3: 제약바이오산업단 | BB3: 연구원 | BC3: 해외 제약 전문가 컨설팅 지원사업 수행 | BD3: 재직 중 | BE3: 계약직 | BF3: 한국보건산업진흥원 | BG3: 1년3개월 | BH3: 2024.04.01 | BI3: 2025.06.30 | BJ3: 외국인환자유치단 | BK3: 연구원(계약직) | BL3: 홈페이지 총괄운영(메디컬코리아홈페이지, 국제의료정보포털), 외국인환자 유치 및 의료기관 진출 홍보물 제작, 한국 의료서비스 인식도 보고서 발간, 메디컬코리아 콘퍼런스 행사 준비 | BM3: 계약 만료에 의한 퇴직 | BN3: - | BO3: - | BP3: - | BQ3: - | BR3: - | BS3: - | BT3: - | BU3: - | BV3: - | BW3: - | BX3: - | BY3: - | BZ3: - | CA3: - | CB3: - | CC3: - | CD3: - | CE3: - | CF3: - | CG3: - | CH3: - | CI3: - | CJ3: - | CK3: - | CL3: - | CM3: - | CN3: - | CO3: - | CP3: - | CQ3: - | CR3: - | CS3: - | CT3: - | CU3: - | CV3: - | CW3: - | CX3: - | CY3: - | CZ3: - | DA3: - | DB3: - | DC3: - | DD3: - | DE3: - | DF3: - | DG3: - | DH3: - | DI3: - | DJ3: - | DK3: - | DL3: - | DM3: - | DN3: - | DO3: - | DP3: - | DQ3: - | DR3: - | DS3: - | DT3: - | DU3: - | DV3: - | DW3: - | DX3: - | DY3: OPIc(영어) | DZ3: Intermediate Mid 3 | EA3: 2025.04.26 | EB3: 205119614572 | EC3: - | ED3: - | EE3: - | EF3: - | EG3: - | EH3: - | EI3: - | EJ3: - | EK3: - | EL3: - | EM3: - | EN3: - | EO3: - | EP3: - | EQ3: - | ER3: - | ES3: - | ET3: - | EU3: - | EV3: - | EW3: - | EX3: - | EY3: - | EZ3: - | FA3: - | FB3: - | FC3: - | FD3: - | FE3: - | FF3: - | FG3: - | FH3: - | FI3: 1 | FJ3: 한국사능력검정시험(1급) | FK3: 국사편찬위원회 | FL3: 72-113573 | FM3: 2024.10.31 | FN3: - | FO3: - | FP3: - | FQ3: - | FR3: 국제의료사업지원 - 15학점 | FS3: 사법일반이론 연구 | FT3: 국제의료사업지원 | FU3: - | FV3: - | FW3: - | FX3: 민법 일반 이론 연구, 계약법 관련 주요 판례 분석 | FY3: 3 | FZ3: - | GA3: - | GB3: 정책법학이론연구 | GC3: 국제의료사업지원 | GD3: - | GE3: - | GF3: - | GG3: 입법학 이론 연구 및 사례 조사 | GH3: 3 | GI3: - | GJ3: - | GK3: 대체적 분쟁해결 특수 연구 | GL3: 국제의료사업지원 | GM3: - | GN3: - | GO3: - | GP3: 대체적 분쟁해결 이론 및 적용 사례 조사 연구 | GQ3: 3 | GR3: - | GS3: - | GT3: 행정법 | GU3: 국제의료사업지원 | GV3: - | GW3: - | GX3: - | GY3: 행정법 이론 연구 | GZ3: 3 | HA3: - | HB3: - | HC3: 국제경제학 | HD3: 국제의료사업지원 | HE3: - | HF3: - | HG3: - | HH3: 통상, 무역, 정책, 미시경제 | HI3: 3 | HJ3: - | HK3: - | HL3: 국제의료사업지원 - 14시간 | HM3: 보건복지부 정보화사업기획과정 | HN3: 국제의료사업지원 | HO3: 14 | HP3: - | HQ3: - | HR3: - | HS3: 보건복지부 산하 공공기관 대상 정보화사업 기획 및 역량강화 교육 | HT3: 한국보건복지인재원 | HU3: - | HV3: - | HW3: - | HX3: - | HY3: - | HZ3: - | IA3: - | IB3: - | IC3: - | ID3: - | IE3: - | IF3: - | IG3: - | IH3: - | II3: - | IJ3: - | IK3: - | IL3: - | IM3: - | IN3: - | IO3: - | IP3: - | IQ3: - | IR3: - | IS3: - | IT3: - | IU3: - | IV3: - | IW3: - | IX3: - | IY3: - | IZ3: - | JA3: 14 | JB3: 1490 | JC3: 1475 | JD3: 1393 | JE3: 1355 | JF3: 0423 | JG3: 비해당 | JH3: 비해당 | JI3: 비해당 | JJ3: 비해당 | JK3: 비해당 | JL3: 해당(경북) | JM3: 비해당 | JN3: 비해당 | JO3: 해당 | JP3: 비해당 | JQ3: 한국보건산업진흥원의 국제의료사업은 성공적인 외국인환자유치 및 의료해외진출을 위해, 외국인환자에게 안전하고 수준 높은 의료서비스를 제공하고, 국내 의료기관의 해외 진출 지원을 목표로 합니다. 이를 위해 법∙제도 개선, 국내외 의료서비스 시장 분석을 통한 유치∙진출 전략 수립, 지원사업 운영, 브랜드 관리 및 홍보 등의 기능을 수행하고 있습니다. ‘보건의료 법∙제도’와 ‘의료서비스 시장’에 대한 이해는 국제의료사업을 수행을 위해 반드시 필요하다 생각합니다. 진흥원의 국제의료사업은 『의료 해외진출 및 외국인환자 유치 지원에 관한 법률』을 근거로 합니다. 국제의료사업은 법과 제도에 기반하여 사람의 생명∙신체에 직결되는 의료서비스가 안전하고 효과적으로 제공되도록 설계되었습니다. 의료서비스의 무분별한 상업화를 방지하면서, 국가적 신뢰를 기반으로 국제적인 경쟁력을 확보해야 하는 이중적 목표를 갖고 있기에, 법제도에 대한 이해가 중요합니다. 동시에 글로벌 의료서비스 시장에 대한 이해 또한 요구 됩니다. 효과적인 전략 수립을 위해 의료서비스 유형별, 국가별, 문화, 소비, 제도 등의 시장 분석이 필요합니다. 법학 학사 및 석사 과정을 통해 법∙제도에 대한 이해를 쌓아왔으며, 진흥원의 업무 경험을 통해 국제의료사업에 대한 역량을 준비하였습니다. 학부에서는 법학과 경제학을 복수전공 하였고, 석사과정에서는 ‘보건의료데이터의 안전한 활용을 위한 법제 연구’를 주제로 개인정보의 보호와 활용의 균형에 대해 연구하였습니다. 실무에서는 외국인환자 유치 실적을 기반으로 ‘외국인 환자가 많이 찾는 의료기관 책자’ 제작 업무를 맡아, 보건의료 데이터 활용을 경험하였습니다. Raw data를 분석∙가공 하여 병원 유형별, 진료과별, 국적별, 지역별 등 기준으로 정리하고 154개 의료기관 정보를 5개 언어로 번역∙검수 하여 책자로 제작한 경험은, 제가 연구했던 보건의료 데이터의 ‘공익적 활용과 정보보호의 균형’이라는 주제를 실무에서 경험할 수 있는 뜻 깊은 일이었습니다. 또한 ‘한국 의료서비스 해외 인식도 조사’ 보고서 발간 업무를 수행하며, 한국의료에 대한 인지도∙신뢰도∙접근성∙경쟁국과의 비교 등 다양한 요소를 고려한 데이터 분석을 통한 전략 국가 도출 과정을 경험하였습니다. 단순한 수치 해석을 넘어 정책적, 사업적 전략 수립을 도출했던 경험을 통해 실무적 역량과 시각을 넓힐 수 있었습니다. 이러한 경험을 바탕으로 ‘2025 메디컬코리아 콘퍼런스’ 준비에 참여하여, 전시홍보관 총괄 및 콘퍼런스 등록 업무를 담당하였습니다. 22개 외국인환자 유치 및 진출 의료기관과 유관단체를 섭외하고, 현장 미팅을 조율하며 진흥원이 수행하는 정책적 사업이 실질적 유치∙진출 성과로 이어지는 과정을 보며 업무의 자부심을 느낄 수 있었습니다. 법∙제도에 대한 이해와 데이터 분석 업무 경험을 바탕으로, 보건의료 정책과 현장의 연결을 함께 볼 수 있었습니다. 이러한 저의 역량을 지속적으로 발전시켜 학문과 경험을 실무에 적용하며, 국제의료사업의 발전에 이바지 하고 싶습니다. | JR3: [보건의료 제도와 산업의 가교역할] 한국보건산업진흥원은 우수한 한국의료 서비스와 제약∙바이오 산업이 글로벌 시장에서 경쟁력을 갖추고 성장할 수 있도록, 제도적∙산업적 기반을 마련하는 기관이라고 생각합니다. 국내 의료기관의 해외 진출, 외국인환자유치, 제약∙바이오 기업과 연구자들이 글로벌 시장에 성공적으로 참여할 수 있도록 국가 차원의 제도 정비와 현장 맞춤형 전략을 함께 수립하는 것이 진흥원의 핵심 역할이라 생각합니다. 진흥원의 업무 경험을 통해, 진흥원은 단순한 관료 조직이 아닌, 산업과 현장을 이해하고 함께 뛰는 실천적 파트너로서 기능하고 있다고 느꼈습니다. 특히, 국제의료사업과 제약바이오산업 업무 경험을 통해, 국내 의료기관과 사업자 및 중소 제약업체에 대한 제도적 지원과 역량강화 사업을 수행하며, 한국 보건의료 산업 발전에 기여하는 진흥원의 역할을 체험할 수 있었습니다. 즉, 진흥원의 핵심가치는 산업과 제도 가교 역할을 통해, 보건의료 산업의 공공성과 글로벌 경쟁력을 함께 발전시켜나가는 조직이라 생각합니다. [생명윤리와 사회적 책임] 보건의료산업은 개인의 생명∙신체∙건강에 직결된 분야로서, 생명에 대한 높은 윤리의식과 사회적 책임이 필요합니다. 특히 진흥원의 국제의료사업은 한국의료를 전 세계에 알리는 역할을 담당하는 만큼, 제도 이해와 시장 분석 능력 뿐 아니라, 한국의료를 대표한다는 사명감과 의료의 공공성, 환자의 생명에 대한 윤리 의식이 무엇보다 중요하다 생각합니다. 외국인환자를 대상으로 의료서비스를 제공하거나, 의료기관의 해외 진출을 지원하는 과정에서 단순히 산업적 발전만 추구하는 것이 아닌 환자의 생명과 건강 증진을 위한 태도와 사회적 책임이 필요합니다. 또한 외국인환자 뿐 아니라 국내 환자의 생명과 건강이 경시되지 않도록 주의해야 하며, 외국인 환자를 이해하기 위하여 환자의 문화적 배경과 권리 등에 대한 균형있는 시각이 필요합니다. ‘정확한 정보의 효과적 전달, 정보 접근성 향상’을 통해 생명윤리와 사회적 책임을 실현할 수 있다고 생각합니다. 외국인환자에게 안전하고 신뢰할수 있는 의료서비스를 선택하고 이용할 수 있도록 조력하는 것이 중요합니다. 진흥원 업무 중 한국의료에 대한 정보를 제공하는 홈페이지 관리 업무를 경험하였습니다. 단순히 보고서, 자료 등을 업로드하는 것이 아닌, 일반 국민과 외국인도 이해할 수 있도록 홈페이지의 디자인 구성, 용어, 표현 등을 보완하기 위하여 노력하였습니다. 특히 생명, 건강에 직결되는 정보일 수록 전문성과 함께 사용자가 인식하기 쉽게 전달되어야 한다고 생각하였습니다. 또한, 다국어 콘텐츠를 제작하며 외국인환자가 진흥원의 사업과 한국의 의료기관, 의료서비스에 대한 정보를 효과적으로 이해하고 활용할 수 있는 방안을 고민하였습니다. 실질적으로 외국인환자에게 필요한 정보를 중심으로 콘텐츠를 구성하고, 디자인하는 것을 위해 노력하였습니다. 진흥원의 사업이 생명윤리와 사회적 책임을 바탕으로 국제적 경쟁력을 갖추도록 하는것에 기여하고 싶습니다. | JS3: [공감과 소통을 통한 문제 해결 - 사례1) 글로벌 입법캠프] 학부와 대학원 시절, 한국∙캄보디아∙태국 법학과 학생들이 모여 각 국가의 법제 개선이 필요한 이슈를 나누고 입법제안을 위해 연구하는 프로젝트에 참여하였습니다. 프로그램의 초기 목표은 ‘한국의 성공적인 법제와 정책을 소개하고, 이를 통해 동남아시아의 사회적 문제 해결을 위한 법제연구’ 이었습니다. 그러나 실제로 캄보디아∙태국 학생들을 만나보니, 자국의 사회문제에 대해 공개적으로 논의하는 것에 불편함을 드러냈습니다. 한국 학생들은 이에 크게 당황하였고, 프로그램의 진행이 어려운 상황이었습니다. 사회적 문제 해결을 위한 법제개선 연구는 중요하지만, 각 국가 학생의 입장을 충분히 고려하지 못하였다는 것을 깨달았습니다. 문제 해결을 위해 한국 팀원들을 설득하여, 연구에 앞서 캄보디아와 태국 학생의 입장 고려가 선행되어야 함을 이야기 하였습니다. 외국 학생들에게, 한국 역시 유럽과 미국 등의 법제연구를 통해 여전히 법제 개선과 발전을 위해 노력하고 있다는 점을 설명하였습니다. 이를 통해 각 국가의 사회적 문제와 법제 개선에 대한 공감대를 형성할 수 있었습니다. 이후 캄보디아의 ‘공공병원 의사의 개인병원에서의 겸직에 따른 공공의료 체계 붕괴 문제’를 주제로 선정할 수 있었습니다. 이에 대하여 한국 공무원의 겸직금지원칙을 인용하여, ‘공공병원 의사의 겸직금지’를 규정하는 의료법 개정안을 제시하였습니다. 이러한 경험을 통해 타 국가 연구자의 입장을 깊이 배려하고 소통하기 위하여는 ‘공감’이 선행되어야 함을 배울 수 있었습니다. 진흥원 업무를 수행하며, 문제와 갈등이 발생하는 경우에 효율성과 문제해결 방안만 강요하는 것이 아니라 소통, 배려, 공감을 바탕으로 문제를 해결해 나갈 것입니다. 동료와 선배, 보직자의 입장을 고려하고 공감하는 태도로 조직에 기여하겠습니다. [공감과 소통을 통한 문제 해결 - 사례2) 지도교수님 연구 참여] 지도 교수님의 연구과제에 학생 연구자로 다수 참여한 경험이 있습니다. 교수님, 선임연구원과의 원활한 소통이 어려운 상황에서, 학생 연구자들 간의 중복 보고와 책임 불분명 문제가 발생하여 팀 내 갈등이 심화되었습니다. 이러한 문제 상황을 해결하기 위해 ‘보고체계와 과제 분담 방식 정비’를 제안하였습니다. 팀 내 주간업무 보고 담당자, 연구 자료 취합 담당자를 지정하고, 학생 각자의 상황을 고려하여 과제 분량을 조정하였습니다. 보고 이전 취합 담당자가 각자의 업무 수행도를 점검하여 공유하였고, 학생간 랩미팅, 교수님과의 랩미팅을 병행하였습니다. 이를 통해 학생들 간 갈등을 최소화 하고 연구과제를 성공적으로 마무리 한 경험이 있습니다. 이러한 경험을 바탕으로 진흥원 업무 수행 시, 원활하고 체계적인 소통을 위한 업무 수행 방법을 끊임없이 고민하고 적용해 나가도록 하겠습니다. | JT3: [제도와 산업에 대한 종합적 이해능력과 문제해결 역량] 저의 강점은 ‘법∙제도∙산업에 대한 종합적 이해 능력’과 ‘제도와 현장을 연결하는 문제해결 역량’입니다. 법학 석사 과정에서 보건의료 데이터의 보호와 활용 방안에 대한 연구를 통해 정책과 현장을 함께 이해하는 문제 해결 역량을 키울 수 있었습니다. 또한 지도교수님, 선임박사님과의 다수 연구 경험을 통해 리서치 및 분석 능력과 의사소통 역량을 준비하였습니다. 이를 바탕으로 제도와 산업의 가교 역할을 하는 진흥원의 사업에 실질적으로 기여할 수 있을 것이라 기대합니다. 진흥원의 업무 경험을 통해, 진흥원은 ‘현장에 기반한 정책 실현’과 이를 위한 ‘유연한 협업’ 을 중요시하는 조직문화를 가지고 있다고 생각했습니다. 특히 외국인환자 유치를 위하여 복잡한 제도나 데이터를 일반인과 외국인이 이해하기 쉽게 설명하거나, 제도 개선을 위한 현장의 목소리 청취 하는 사업을 통해, 국제의료사업은 단순한 수치분석을 넘어 정치∙경제∙사회∙문화적 배경의 종합적 이해를 바탕으로 전략 수립이 필요하다는 점을 깨달았습니다. 실제로 한국의료 홍보를 위한 다국어 홈페이지 운영, 다국어 홍보 콘텐츠 제작, 인식도 조사 보고서 발간, 국제 행사 준비 등에 참여하며 현장의 요구와 제도 간의 효과적인 조율을 경험할 수 있었습니다. 또한, 저는 적극적인 소통을 바탕으로 구성원간 협업 업무에 기여할 수 있습니다. 국제의료사업의 홍보 업무를 담당하며, 부서 내 다양한 사업 담당자와 소통하며 내용을 취합, 정리하여 콘텐츠로 제작한 경험이 있습니다. 나아가 국제 행사준비 과정에서의 현장 실무자들과의 소통 경험, 진흥원 내 보직자들과의 소통 과정에서 정확한 정보와 신뢰를 전달하기 위하여 노력하였습니다. 이러한 경험을 바탕으로 진흥원 입사 후 부서 간, 기관 간, 국내외 이해관계자 간의 소통을 유연하게 이끌어 발전적인 성장에 기여하고 싶습니다. [보완점에 대한 인식과 개선 노력] 저는 ‘업무 처리 속도’에 대한 보완이 필요하다 생각합니다. 실무 경력이 상대적으로 짧고, 처음 수행하는 업무에 대한 이해와 숙지를 위한 시간이 다소 필요하였으며, 실수를 줄이기 위한 반복 검토로 인해 빠른 대응이 늦어지는 경우가 있었습니다. 진흥원에서 업무를 경험하며 ‘완벽하게 계획하는 것’ 보다 ‘주어진 시간 내에 유연하게 대응 하는 것’이 효과적인 경우가 많다는 점을 배웠습니다. 이를 통해 일의 중요도, 우선순위, 일정에 따라 업무를 분배하여 처리하고 피드백을 받으며 업무의 속도감과 완성도를 함께 높이기 위해 노력하고 있습니다. 앞으로도 유연하고 정확한 업무처리, 환경 변화에 대한 순발력있는 대응, 업무에 대한 책임의식을 갖고 진흥원에 기여하는 실무형 인재로 꾸준히 성장해 나가길 기대합니다.
A4: 0005-000026 | B4: 이보연 | C4: 1지망 : 보건산업진흥지원-정규직-전문직/연구원-오송 | D4: 03_보건산업진흥지원-정규직-전문직/연구원-오송 | E4: 1 | F4: 2025.07.18 | G4: 제출완료 | H4: 2025.07.30 | I4: Lee Boyeon | J4: boyun324@naver.com | K4: 010-4019-4315 | L4: 010-4163-9413 | M4: 해당없음 | N4: 해당없음 | O4: 비대상 | P4: - | Q4: - | R4: - | S4: - | T4: - | U4: - | V4: - | W4: - | X4: - | Y4: - | Z4: - | AA4: - | AB4: - | AC4: - | AD4: - | AE4: - | AF4: - | AG4: - | AH4: - | AI4: - | AJ4: - | AK4: - | AL4: - | AM4: - | AN4: - | AO4: - | AP4: - | AQ4: - | AR4: - | AS4: - | AT4: - | AU4: 5년10개월 | AV4: 정규직 | AW4: 엔에이백신연구소 | AX4: 2년7개월 | AY4: 2023.01.01 | AZ4: 재직중 | BA4: 개발본부 임상팀 | BB4: 대리 | BC4: (R&D 기획) 백신 및 면역항암제 개발 전략 수립, (문헌 조사) 임상/비임상 문헌 조사 및 자료 기획, (임상개발) 임상시험 시놉시스 작성 및 식약처 사전상담 대응 등 IND 제출 준비 및 초기 임상개발 전반을 담당 | BD4: 보건산업 정책·기획 분야 도전 희망 | BE4: 정규직 | BF4: 퓨전바이오텍 | BG4: 2년9개월 | BH4: 2020.03.02 | BI4: 2022.12.29 | BJ4: 개발팀 | BK4: 대리 | BL4: (비임상 기획) 노인성 황반변성 치료제 비임상 독성시험 기획, (CRO 관리) CRO 계약 및 일정 관리, (프로젝트 관리) 개발 일정 및 재고관리 체계 수립, (연구 전략 기획) 외부 전문가 자문을 통한 신약 개발 전략 수립 등 전임상 연구 기획 및 운영, (국가과제 수행) 국가과제 제안서 작성 및 수행, (투자유치) IR 자료 제작 및 VC 미팅 참석 등 투자유치 지원 업무 | BM4: 임상 및 기획 업무로의 커리어 전환을 위함 | BN4: 인턴(공공기관 외) | BO4: ㅇㅇ대학교 | BP4: 6개월 | BQ4: 2019.09.01 | BR4: 2020.03.01 | BS4: 산학협력단 | BT4: 인턴 | BU4: 청년 TLO 육성사업 참여, 특허 기반 기술이전 교육 수료 및 특허자료 정리 업무 수행. 이후 교내 벤처기업(퓨전바이오텍)으로 파견되어 신약개발 초기 연구개발 실무 수행 | BV4: 계약기간 만료 | BW4: - | BX4: - | BY4: - | BZ4: - | CA4: - | CB4: - | CC4: - | CD4: - | CE4: - | CF4: - | CG4: - | CH4: - | CI4: - | CJ4: - | CK4: - | CL4: - | CM4: - | CN4: - | CO4: - | CP4: - | CQ4: - | CR4: - | CS4: - | CT4: - | CU4: - | CV4: - | CW4: - | CX4: - | CY4: - | CZ4: - | DA4: - | DB4: - | DC4: - | DD4: - | DE4: - | DF4: - | DG4: - | DH4: - | DI4: Toeic Speaking test | DJ4: Advanced Low | DK4: 2025.01.26 | DL4: 100979 | DM4: - | DN4: - | DO4: - | DP4: - | DQ4: - | DR4: - | DS4: - | DT4: - | DU4: - | DV4: - | DW4: - | DX4: - | DY4: - | DZ4: - | EA4: - | EB4: - | EC4: - | ED4: - | EE4: - | EF4: - | EG4: - | EH4: - | EI4: - | EJ4: - | EK4: - | EL4: - | EM4: - | EN4: - | EO4: - | EP4: - | EQ4: - | ER4: - | ES4: - | ET4: - | EU4: - | EV4: - | EW4: - | EX4: - | EY4: - | EZ4: - | FA4: - | FB4: - | FC4: - | FD4: - | FE4: - | FF4: - | FG4: - | FH4: - | FI4: 1 | FJ4: 컴퓨터활용능력2급 | FK4: 대한상공회의소 | FL4: 25-K9-044553 | FM4: 2025.07.22 | FN4: - | FO4: - | FP4: - | FQ4: - | FR4: 보건산업진흥지원 - 15학점 | FS4: 기업가 정신과 혁신 | FT4: 보건산업진흥지원 | FU4: - | FV4: - | FW4: - | FX4: (기술창업 실무 체험) 기업가정신의 이론적 기반과 실제 적용 사례를 학습하고, 팀 프로젝트를 통해 실제 창업 상황을 가정한 비즈니스 모델 기획 및 발표를 수행한 과목. 시장조사, 수요분석, 비즈니스 모델 캔버스 작성, 차별화 전략 수립, 피칭 발표까지 전 과정에 참여하며 기술창업의 전반적 흐름과 실행 방법론을 체득함. (직무 관련성) 기술사업화 및 창업지원 시 기업의 입장을 이해하는 기반 지식으로 활용할 수 있음. | FY4: 3 | FZ4: - | GA4: - | GB4: 현대생명과학동향 | GC4: 보건산업진흥지원 | GD4: - | GE4: - | GF4: - | GG4: (생명과학 기술 트렌드 이해) 최신 생명과학 연구 및 기술 동향을 분석하고, 논문과 사례 발표를 통해 변화하는 생명과학 기술의 산업적 영향력을 이해한 과목. (직무 관련성) 국내외 산업 동향 분석, 보건산업 정책 및 연구 기획 시 필요한 기초 지식으로 활용할 수 있음. | GH4: 3 | GI4: - | GJ4: - | GK4: 생명공학개론 | GL4: 보건산업진흥지원 | GM4: - | GN4: - | GO4: - | GP4: (생명공학 기술 학습) 생명공학 기술의 개념, 응용 분야, 산업 적용 사례 등을 포괄적으로 다룬 과목. 유전자 조작, 단백질 공학, 조직공학 등 생명공학 기반 기술이 어떻게 적용되는지 학습함. (직무 관련성) 신약 기술 검토 및 바이오의약품 개발 지원 시 기술적 이해를 위한 기반 지식으로 활용할 수 있음. | GQ4: 3 | GR4: - | GS4: - | GT4: 면역학 | GU4: 보건산업진흥지원 | GV4: - | GW4: - | GX4: - | GY4: (면역 반응 메커니즘 이해) 선천면역과 후천면역의 작동 원리, 백신의 작용 메커니즘, 항체와 항원 간 상호작용, 자가면역 질환 등 면역학의 핵심 개념을 학습한 과목. 특히, 바이오의약품 및 백신 개발의 기초가 되는 면역세포 활성화, 면역 반응 조절 메커니즘 등을 깊이 있게 이해함. (직무 관련성) 바이오의약품 메커니즘에 대한 이해 능력, 신약 및 백신 관련 정책·지원 사업 수행 시 요구되는 생물학적 기반 지식으로 활용할 수 있음. | GZ4: 3 | HA4: - | HB4: - | HC4: 고급세포생물학 | HD4: 보건산업진흥지원 | HE4: - | HF4: - | HG4: - | HH4: (세포 신호전달·사멸 기전 심화 학습) 세포 구조 및 기능에 대한 심화 이론을 중심으로, 세포 내 신호전달, 세포 분열, 세포사멸, 세포간 상호작용 등을 분자적 수준에서 이해하는 과목. (직무 관련성) 특히 바이오의약품 개발, 항암제, 세포치료제와 직접적으로 연결되는 기초 지식으로 활용할 수 있음. | HI4: 3 | HJ4: - | HK4: - | HL4: 보건산업진흥지원 - 145시간 | HM4: 의약품 규제업무 전문가 양성과정 | HN4: 보건산업진흥지원 | HO4: 100 | HP4: - | HQ4: - | HR4: - | HS4: (의약품 전주기 규제) 약사법, 임상시험, 품목허가, GMP, 특허, 안전관리 등 의약품 개발 전주기에 대한 규제지식을 학습하고 수료시험을 통과함. (직무 관련성) 의약품 정책과 규제 이해를 바탕으로 제약·바이오 사업 기획 및 정책 수립 시 법적 기반을 갖춘 기획 역량을 발휘할 수 있음. | HT4: 식품의약품안전처/한국에프디시법제연구원 | HU4: 신약개발 Project Management 사례중심과정 | HV4: 보건산업진흥지원 | HW4: 6 | HX4: - | HY4: - | HZ4: - | IA4: (R&D 기획 및 평가) 신약개발 전임상·임상·허가 전 과정을 중심으로 단계별 일정 및 리스크 관리, 전략 수립, 기획·성과 평가 방법을 사례 기반으로 학습함. (직무 관련성) 보건산업 R&D 지원 및 정책사업 성과관리 업무 시 단계별 일정 및 리스크 관리에 활용할 수 있음. | IB4: 한국보건복지인재원 | IC4: 글로벌기술사업화 아카데미(전략과정) | ID4: 보건산업진흥지원 | IE4: 24 | IF4: - | IG4: - | IH4: - | II4: (기술사업화 전략) 기술이전, 가치평가, 포트폴리오 관리, 오픈이노베이션, 투자전략 등 사업화 및 라이센싱 전략 수립 역량을 강화함. (직무 관련성) 기술사업화와 라이센싱 관련 실무지식을 기반으로 창업지원 또는 기술사업화 지원사업 기획 및 운영에 활용할 수 있음. | IJ4: 제약바이오 사업개발연구회 | IK4: 제약바이오헬스산업 스타트업 창업 및 성장전략 아카데미 | IL4: 보건산업진흥지원 | IM4: 14 | IN4: - | IO4: - | IP4: - | IQ4: (창업 및 사업계획) 제약∙바이오 창업을 위한 R&D·인허가 전략, 사업계획서 작성, 비즈니스 모델 수립 등 스타트업 성장단계별 전략을 학습함. (직무 관련성) 창업 전략 및 비즈니스 모델 수립 역량을 바탕으로 보건산업 창업지원 프로그램의 설계 및 지원 업무 시 활용할 수 있음. | IR4: 한국신약개발연구조합 | IS4: 국가연구개발사업 성과평가의 실제(입문) | IT4: 보건산업진흥지원 | IU4: 1 | IV4: - | IW4: - | IX4: - | IY4: (성과평가 제도 이해) 국가 R&D사업의 추진체계, 성과지표, 통계 시스템 등 성과평가 제도 전반에 대한 이해를 통해 정책기획 및 평가 역량을 함양함. (직무 관련성) 보건산업 분야의 연구개발 성과를 분석하고 정책성과 평가 업무에 필요한 기반 지식으로 활용할 수 있음. | IZ4: 과학기술인력개발원 | JA4: 145 | JB4: 1473 | JC4: 1480 | JD4: 1481 | JE4: 1475 | JF4: 0324 | JG4: 비해당 | JH4: 비해당 | JI4: 비해당 | JJ4: 비해당 | JK4: 비해당 | JL4: 해당(울산) | JM4: 비해당 | JN4: 비해당 | JO4: 비해당 | JP4: 비해당 | JQ4: [신약개발 전주기 이해를 바탕으로 실질적 전략 수립에 기여] 해당 직무는 제약·바이오 및 의료기기 등 보건산업 분야의 기술사업화와 창업을 촉진하기 위해, 유망 기술이나 아이템을 보유한 연구기관, 병원, 기업 등을 대상으로 기술이전, 기술평가, 창업지원, 글로벌 진출 등 전주기적 지원을 기획·운영하는 역할을 수행한다고 이해하고 있습니다. 또한, 산업별 정책 및 전략을 수립하고, 사업 운영 및 인재 양성 등 다양한 사업화 기반을 마련함으로써 보건산업 전반의 경쟁력 제고에 기여하는 직무라고 생각합니다. 이러한 역할을 수행하기 위해서는 수요기관의 입장과 제품 개발 과정에서의 주요 허들을 실무적인 관점에서 이해하고 있어야 합니다. 이를 통해 수요자 상황과 니즈를 고려한 맞춤형 지원 프로그램을 기획할 수 있으며, 사업 관리 과정에서 수요자가 겪는 어려움을 파악해 보다 효과적인 지원책을 도출하고 사업 실효성 확대에 기여할 수 있다고 생각합니다. 저는 제약·바이오 벤처기업에서 백신 신약 개발과 대관 업무를 중점적으로 수행하며 제약 산업의 실무 전반을 경험했습니다. 이를 통해 다음 두 가지 역량을 갖추게 되었습니다. 첫째, 신약개발 전주기에 대한 이해, 둘째, 관련 산업의 생태와 규제 요인에 대한 이해입니다. 우선 신약개발의 전 과정을 이해하고 있습니다. 교모세포종 항암 백신과 대상포진 예방 백신 개발 프로젝트에 참여하여 CRO 계약을 주도했고, 임상 준비 단계까지의 과학적·규제적 요구사항에 대응하는 실무 경험을 쌓았습니다. 특히 ‘의약품 인허가를 위한 비임상-임상 연계’ 교육을 통해 배운 내용을 실무에 직접 적용하여 분석법 밸리데이션, 독성시험, 약물동태시험 등 주요 비임상 항목을 명확히 제시하고, CRO에 대응하며 주요 보고서 25건을 확보하는 등 신약개발 과정에 대한 전문성을 갖췄습니다. 해당 경험을 통해 향후 보건산업의 정책 기획과 수요자 맞춤형 지원을 통해 사업 성과 확대에 기여하겠습니다. 또한, 규제 대응 역량도 갖추고 있습니다. ‘의약품 규제업무 전문가 양성과정’을 수료해 약사법, 품목허가, 시판 후 안전관리 등 제약 규제 전반에 대한 실무 지식을 갖췄습니다. 실제로 식약처 사전상담을 직접 대응하면서, IND 제출을 위한 요구 자료에 기반한 전임상 및 임상 개발 전략 수립에도 기여하였고 이를 통해 제약·바이오 산업의 생태계에 대한 이해와 규제 대응 역량을 갖췄습니다. 규제에 대한 선제적 이해는 제품 개발 성공 가능성을 높이는 중요한 요소이기 때문에 향후 사업 기획 시 수요자 지원 전반에 리스크 요인을 선제적으로 파악해 업무를 수행하겠습니다. 제가 가진 신약개발 실무 경험과 규제 대응의 중요성을 이해하는 역량은, 수요자의 기술력과 시장성, 대응해야 할 허들을 분석하고 맞춤형 사업화 전략을 지원하는 데 실질적인 강점이 될 수 있습니다. 입사 이후 수요자와 긴밀한 소통과 정책 동향 파악을 통해 보건산업의 지속 가능한 맞춤형 사업을 기획하는 데 제가 가진 전문성을 적극 활용하도록 하겠습니다. | JR4: [실행으로 입증한 실무자의 책임감] 진흥원은 공공기관으로서, 한정된 재원을 전략적으로 일부 연구기관과 기업을 지원하며, 보건산업의 효과적인 성장과 국민 건강권 향상이라는 공익적 가치를 추구합니다. 이러한 정책 자금의 수립과 집행은 수요자에 대한 깊은 이해는 물론, 원칙의 준수와 공정한 절차를 통해 이해관계자 간의 신뢰를 형성할 수 있습니다. 이러한 조직에서 가장 중요한 가치는 ‘책임감’이라고 생각합니다. ‘책임감’이란 맡은 바 업무를 통해 조직의 성장에 실질적으로 기여하는 것이라 생각합니다. 진흥원은 공익적 가치를 실현하는 기관인 만큼, 모든 구성원은 국민과 국가, 조직에 기여한다는 책임감을 바탕으로 업무에 임해야 합니다. 처음 실무에 투입되었을 때는 결과에 대한 부담감이 커 상사의 결정에 수동적으로 따르는 편이었습니다. 하지만 상사께서 부담 갖지 말고 제 생각을 이야기해도 된다고 격력해 주셨고, 책임 있는 실무자가 되기 위해 제 태도를 적극적으로 바꿔야겠다고 결심했습니다. 이후 저는 회의 전에 자료를 사전에 정리해 의견을 준비하거나 책임 있는 의견 개진을 실천하려고 노력했습니다. 실제로 제 아이디어가 반영되어 좋은 결과를 만들게 되면서 점차 자신감이 생겼고, 이후부터는 조직의 목표를 함께 짊어지는 실무자로서의 태도를 갖게 되었습니다. 이러한 변화는 타겟 질환 전환 여부를 논의하던 회의에서 실질적인 기여로 이어졌고, 저는 실무자로서 책임 있는 의견 개진이 조직 전체의 성과에 기여할 수 있음을 체감했습니다. 일례로 교모세포종 백신의 임상시험을 준비하던 중, 개발 회의에서 대표님께서 비용 절감을 위해 타겟 질환 변경을 제안하신 적이 있었습니다. 당시 연구팀은 기술적 가능성을 검토 중이었기에 저는 임상팀의 입장에서 실제로 임상 비용 절감에 기여할 수 있는지 현실성과 영향을 확인할 필요가 있다고 판단했습니다. 이에 상무님과 협의하여 임상팀 차원의 검토 자료를 준비했고, 개발팀과의 유기적 소통을 통해 임상팀의 의견을 정리한 뒤 회의에서 경쟁 현황, 질환 통계 자료, 임상 시나리오 4가지와 그에 따른 장단점 등 관련 자료를 소개하고, 예상되는 문제점을 표로 정리해 발표했습니다. 이 과정에서 연구팀이 지적한 기술적 문제점에 실질적 근거를 더하며, 최초 개발 전략의 강점과 효과에 대해 구성원들이 다시 확신을 가질 수 있도록 도왔습니다. 그 결과 회사가 겪을 수 있었던 잠재적 위험을 사전에 회피하고 개발 성과를 극대화하는 데 기여할 수 있었습니다. 공공기관의 구성원으로서 책임감은 수요 기관에 대한 적극적이고 실질적인 지원에서 발휘되어야 한다고 생각합니다. 저는 바이오 벤처에서 근무하며 정책 기관의 지원이 실무 현장에 얼마나 큰 힘이 되는지 체감해 왔습니다. 기관의 철학과 규정을 준수하는 범위 내에서, 수요 기관이 필요로 하는 지점을 정확히 파악하고, 책임을 다해 그에 맞는 최적의 도움을 제공하겠습니다. 이를 통해 국내 바이오 생태계의 성장과 국민 건강 증진을 위한 책임을 다하는 공공기관의 구성원이 되겠습니다. | JS4: [정보 격차를 좁혀 협업의 실마리를 만들다] 외부 협력 업체에 개발 의약품 소개 자료를 만드는 과정에서, 펩타이드 항암 백신의 개발 방향인 목표제품 특성(TPP)을 수립하는 데 있어 부서 간 협업의 어려움을 극복해 성과를 낸 사례가 있습니다. 당시 연구팀, 생산팀, 품질팀, 임상팀의 중심에서 데이터를 취합하고 근거 자료를 확보해야 했습니다. 하지만 저는 비임상과 임상 분야에는 익숙했으나, 제조, 품질 및 안정성 지표 설정 등의 생산과 CMC 파트는 경험이 부족해 내용을 구성하는데 한계가 있었습니다. 더군다나 기존 유사 문서나 사례도 없어, 내부 협업 없이는 완성도 있는 문서를 만들 수 없는 상황이었습니다. 이에 타 부서에 자료 확보와 관련해 협업을 요청했지만 문제가 있었습니다. 각 부서가 분업적으로 일해왔기 때문에 서로의 업무 목표와 언어가 달라 협업에 소극적이었다는 점입니다. 특히 제가 요청하는 자료가 어느 수준까지 필요한지 감이 오지 않아 협조를 미루는 분위기도 있었습니다. 이에 저는 상호 이해 부족이 협력을 어렵게 만든다는 문제의 근본 원인을 파악하고, 이 문제를 해결하기 위해 두 가지 접근을 병행했습니다. 첫째는 부서 간 정보의 비대칭을 줄여 협업 필요성과 협조 요청의 목적을 명확히 전달하는 것이었습니다. 단순히 자료를 요청하는 데 그치지 않고, 타사의 TPP의 예시를 제시하고 구체적인 수치 자료들이 중요 품질 특성과 연계되기 때문에 협력 업체의 이해 증진 과정에서 핵심적으로 작용한다는 점을 설명했습니다. 이를 통해 실무 담당자들도 해당 자료의 중요성을 충분히 인식하게 되었고, 문서의 일관된 양식과 협조 수준을 제시하자 자료들을 효율적으로 취합할 수 있었습니다. 둘째는 서면으로 소통하기에 한계가 있거나, 신속히 수행해야 하는 부분이 있을 때는 미팅을 주도적으로 제안했습니다. 팀별 담당자와 짧은 개별 미팅을 진행하여 사전 설명과 요구사항을 전달하고, 이후 전 부서를 모아 단일 TPP 프레임에 각 정보를 어떻게 통합하면 좋을지 논의했습니다. 여러 담당자가 모이는 만큼 회의가 길어지지 않도록 문제점의 공유 및 해결책의 제시를 중심 사안으로 핵심 위주의 소통이 이루어지도록 주도하였습니다. 이러한 전략을 병행함으로써 효율적으로 부서 간의 협업을 도출할 수 있었고 양질의 자료를 확보해 TPP를 기한 내 성공적으로 작성해 낼 수 있었습니다. 본 TPP 자료는 내부 의사결정과 진도 점검 시에도 폭넓게 활용되었고, 개발 방향과 목표를 구체화함으로써 사전상담 결과도 긍정적으로 도출되어 IND 제출 방향을 명확히 정립할 수 있었습니다. 이 경험을 통해 저는 부서 간 언어가 다르면, 단순한 자료 요청보다는 ‘이해 기반의 연결’이 우선이라는 점을 배웠습니다. 협업의 핵심은 결국 같은 목표를 향한 상호 기여라는 사실을 체감했고, 이후에도 제가 담당하는 모든 프로젝트에서 이 원칙을 실천해 오고 있습니다. 앞으로도 조직 내 다양한 이해관계자와 협업할 때, 정보를 중재하고 통합해 내는 실무 리더십을 발휘하겠습니다. | JT4: [강점: 다양한 정보를 수집·분석해 전략화하는 역량 - 수요자 관점에서 설계하는 정책 실행가] 저는 시장, 기술 및 규제 정보를 통합적으로 분석하고 전략화하는 역량을 갖추고 있습니다. 이러한 역량은 진흥원의 정책 기획 및 사업 수행 업무에서 더욱 발전할 수 있는 요소입니다. 진흥원의 보건산업 정책 및 지원사업은 급변하는 보건의료 환경 속에서 수요자 중심의 기획과 전략적 자원 배분이 핵심입니다. 특히 제약·바이오 산업은 높은 규제 장벽과 기술 불확실성을 동반하는 만큼, 시장 동향과 기술 실현 가능성, 인허가 제도 등의 전방위적 요소를 고려하는 능력이 필요합니다. 저는 신약개발 실무를 수행하면서 이와 같은 다요소를 분석해 전략화하는 경험을 쌓아왔고, 이를 적극 활용하여 정책 수요자들이 겪는 실무 현장을 폭넓게 이해할 수 있는 사고 역량을 갖추었습니다. 일례로, 교모세포종 항암백신에 대한 초기 임상 전략을 수립해야 했던 적이 있습니다. 임상 전략은 개발 방향을 결정하는 중요한 내용인 만큼, 성공 사례들에 대한 분석이 필요했습니다. 저는 판단의 근거가 되는 자료를 마련하고자 글로벌 항암백신 임상 79건을 16개 기준으로 분류하고, 이들의 작용 기전, 투여 방식, 병용 요법 등을 바탕으로 성공 사례의 공통 요소를 표 형태로 제시하여 보고서를 작성하였습니다. 이 자료는 사내 개발의 방향성을 결정하는 핵심 근거 자료로 활용되었고 이후 국가 연구개발 과제 선정과 IR 자료 작성에도 활용되는 성과를 거두었습니다. 진흥원 입사 후 정책 기획에 있어 수요자 관점의 정보 분석력을 바탕으로 실효성 있는 사업을 기획하는 전문가로 성장하고자 합니다. 특히, 기회가 된다면 제약바이오산업단에서 전문 인력 양성, 제약·바이오 연구 개발 역량 증대를 위한 지원 등의 업무에 참여하며, 제가 겪어온 다양한 제품군(백신, 면역증강제, 항암제, 점안제 등)에 대한 개발 전략 수립 경험을 적극 적용해 실무 기반의 기획과 현장 친화적 정책 수립에 힘쓰겠습니다. [약점: 공급자 관점의 연구개발 및 예산관리에 대한 이해] 반면 보완해야 할 약점으로는 공급자 관점에서의 국가 보건의료 연구개발 정책 수립과 예산 배분에 대한 경험입니다. 수요자 입장에서 정책의 중요성을 분명히 이해하고 있지만 보다 거시적인 관점에서 국가연구개발 전주기의 체계적 이해는 아직 보완이 필요하다고 느꼈습니다. 이후 이러한 약점을 보완하고자 국가과학기술인력개발원에서 R&D 기획, R&D 프로젝트 관리, 국가연구개발사업 성과평가 등의 교육 3건을 수료하였고, 기업의 사업화 역량 강화를 위한 ‘전담 BD 파트너 프로그램’ 정책 제안에도 참여하며 적극적으로 정책 기획자로서의 입장을 이해하고자 노력해 오고 있습니다. 현재까지 수요자 관점에서의 경험을 축적해 왔고, 스스로 공부하며 공급자의 입장을 이해해본 만큼, 진흥원에 입사한 이후로는 보건의료 R&D 정책 체계에 대한 실무 경험을 지속해서 축적하며, 중장기적으로 정책 제안이 가능한 실무자이자 실행가로 성장하겠습니다.
A5: 0005-000036 | B5: 박지은 | C5: 1지망 : 보건의료연구개발 사업관리A-정규직-전문직/연구원-오송 | D5: 05_보건의료연구개발 사업관리A-정규직-전문직/연구원-오송 | E5: 1 | F5: 2025.07.18 | G5: 제출완료 | H5: 2025.07.30 | I5: Park Ji Eun | J5: eugeneje41@gmail.com | K5: 010-8632-1961 | L5: 010-9188-8314 | M5: 해당없음 | N5: 해당없음 | O5: 비대상 | P5: - | Q5: - | R5: - | S5: - | T5: 게재 | U5: SSCI | V5: Exploring factors affecting knowledge creation in under-researched healthcare topics: a case study of women’s health research | W5: Health Research Policy and Systems, 23, 62 | X5: 주저자 | Y5: 2025.05.20 | Z5: (1/4) | AA5: BMC | AB5: 1478-4505 | AC5: 게재 | AD5: 국내SCIE | AE5: Trend of Women’s Health Research in Korea, 2012–2020: Topic and Text Network Analysis | AF5: Journal of Korean Medical Science, 38, 30, e226 | AG5: 주저자 | AH5: 2023.06.23 | AI5: (1/6) | AJ5: Korean Academy of Medical Sciences | AK5: 1011-8934 | AL5: 게재 | AM5: 국내 등재학술지 | AN5: 생활습관병 예방관리를 위한 가이드라인 개발 현황과 의사의 역할 | AO5: 대한의사협회지, 제61권, 제1호, 62-70쪽 | AP5: 주저자 | AQ5: 2018.01.17 | AR5: (1/4) | AS5: 대한의사협회 | AT5: 1975-8456 | AU5: 2년 | AV5: 계약직 | AW5: 의료정책연구원 | AX5: 2년 | AY5: 2016.08.02 | AZ5: 2018.08.02 | BA5: 의료정책연구원 | BB5: 연구원 | BC5: 국내외 보건의료정책 동향 조사, 정책 실무 협조, 연구보고서 및 논문 작성 | BD5: 박사 입학으로 인한 퇴사 | BE5: - | BF5: - | BG5: - | BH5: - | BI5: - | BJ5: - | BK5: - | BL5: - | BM5: - | BN5: - | BO5: - | BP5: - | BQ5: - | BR5: - | BS5: - | BT5: - | BU5: - | BV5: - | BW5: - | BX5: - | BY5: - | BZ5: - | CA5: - | CB5: - | CC5: - | CD5: - | CE5: - | CF5: - | CG5: - | CH5: - | CI5: - | CJ5: - | CK5: - | CL5: - | CM5: - | CN5: - | CO5: - | CP5: - | CQ5: - | CR5: - | CS5: - | CT5: - | CU5: - | CV5: - | CW5: - | CX5: - | CY5: - | CZ5: - | DA5: - | DB5: - | DC5: - | DD5: - | DE5: - | DF5: - | DG5: - | DH5: - | DI5: - | DJ5: - | DK5: - | DL5: - | DM5: - | DN5: - | DO5: - | DP5: - | DQ5: - | DR5: - | DS5: - | DT5: - | DU5: - | DV5: - | DW5: - | DX5: - | DY5: - | DZ5: - | EA5: - | EB5: - | EC5: - | ED5: - | EE5: - | EF5: - | EG5: - | EH5: - | EI5: - | EJ5: - | EK5: - | EL5: - | EM5: - | EN5: - | EO5: - | EP5: - | EQ5: - | ER5: - | ES5: - | ET5: - | EU5: - | EV5: - | EW5: - | EX5: - | EY5: - | EZ5: - | FA5: - | FB5: - | FC5: - | FD5: - | FE5: - | FF5: - | FG5: - | FH5: - | FI5: - | FJ5: - | FK5: - | FL5: - | FM5: - | FN5: - | FO5: - | FP5: - | FQ5: - | FR5: 보건의료연구개발 사업관리A - 12학점 | FS5: Survey in Science, Technology, and Public Policy | FT5: 보건의료연구개발 사업관리A | FU5: - | FV5: - | FW5: - | FX5: 과학기술과 공공정책의 교차 영역을 다루는 핵심 이론과 실제 사례를 소개하는 과목으로, 정책 형성, 제도 및 조직 분석, 과학기술의 사회적 맥락 등에 관한 질적·양적 정책 분석 방법을 학습하는 수업 | FY5: 3 | FZ5: - | GA5: - | GB5: 과학기술학 통론 | GC5: 보건의료연구개발 사업관리A | GD5: - | GE5: - | GF5: - | GG5: 과학기술이 사회에서 어떻게 생성되고 운영되는지를 구조적으로 이해하기 위한 과목으로, 과학기술 연구와 정책이 내포한 제도적·문화적 맥락, 권력관계와 정치적 의미, 그리고 사회적 가치와 윤리적 쟁점 등에 대한 학습 | GH5: 3 | GI5: - | GJ5: - | GK5: Science, Law and Regulation | GL5: 보건의료연구개발 사업관리A | GM5: - | GN5: - | GO5: - | GP5: 과학기술이 사회에서 법과 제도를 통해 어떻게 규율되고 형성되는지 구조적으로 이해하기 위한 과목으로, 과학기술 규제가 작동하는 법적·정책적 맥락, 제도 설계와 위험 관리 방식, 그리고 기술혁신이 불러오는 윤리적·사회적 쟁점에 대해 학습 | GQ5: 3 | GR5: - | GS5: - | GT5: Technology for Social Justice | GU5: 보건의료연구개발 사업관리A | GV5: - | GW5: - | GX5: - | GY5: 과학기술이 사회에서 어떻게 형성되고 작동하는지 이해하기 위한 수업으로, 과학기술의 사회적 가치에 대한 논의를 다층적으로 탐구하기 위한 과목으로, 고령화, 장애, 도시 모빌리티, 인공지능 등 구체적 사례를 통해 기술이 사회 문제 해결에 어떻게 기여하는지 분석하는 수업 | GZ5: 3 | HA5: - | HB5: - | HC5: - | HD5: - | HE5: - | HF5: - | HG5: - | HH5: - | HI5: - | HJ5: - | HK5: - | HL5: - | HM5: - | HN5: - | HO5: - | HP5: - | HQ5: - | HR5: - | HS5: - | HT5: - | HU5: - | HV5: - | HW5: - | HX5: - | HY5: - | HZ5: - | IA5: - | IB5: - | IC5: - | ID5: - | IE5: - | IF5: - | IG5: - | IH5: - | II5: - | IJ5: - | IK5: - | IL5: - | IM5: - | IN5: - | IO5: - | IP5: - | IQ5: - | IR5: - | IS5: - | IT5: - | IU5: - | IV5: - | IW5: - | IX5: - | IY5: - | IZ5: - | JA5: - | JB5: 1467 | JC5: 1438 | JD5: 1495 | JE5: 1491 | JF5: 1019 | JG5: 비해당 | JH5: 비해당 | JI5: 비해당 | JJ5: 비해당 | JK5: 비해당 | JL5: 비해당 | JM5: 비해당 | JN5: 비해당 | JO5: 비해당 | JP5: 비해당 | JQ5: 저는 보건의료 R&D 사업관리 직무가 국민의 건강과 삶의 질을 향상시키기 위한 보건의료기술을 전략적으로 발굴하고 해당 기술이 실질적으로 개발·도입되어 사회에 기여할 수 있도록 기술의 전주기를 체계적으로 관리하는 역할이라 이해하고 있습니다. 보건의료기술의 전주기를 관리하는 직무는 R&D 사업 지원을 넘어 사회적 수요에 기반한 연구기획, 정책적 타당성 평가, 연구성과의 환류와 확산까지 포괄하는 복합적 직무이자 보건산업진흥원이 지향하는 ‘바이오헬스 산업 혁신과 국민건강 증진을 선도하는 글로벌 리더' 도약의 실현을 위한 중추적인 토대라고 생각합니다. 이 직무를 수행하기 위해서는 두 가지의 균형 잡힌 전문성이 필요하다고 생각합니다. 첫째, 질병 부담이 크거나 사회가 요구하는 건강 문제를 식별할 수 있는 보건의료 전문성이 있어야 하고, 둘째, 해당 문제를 해결할 수 있는 의료기술의 특성과 R&D 제도를 이해하는 전문성이 필요하다고 생각합니다. 저는 이 두 영역의 전문성에 대한 역량을 강화하기 위해, 과학기술과 보건의료를 넘나드는 다학제적 경험을 쌓아왔습니다. 초기에는 생명과학 기반의 연구를 통해 의료기술 개발의 근간이 되는 과학적 원리와 의료기술 적용의 흐름을 이해하였고, 이후 진단기술의 개발 및 적용 가능성에 대한 연구를 수행하며 기술적 한계와 상용화 가능성을 다각도에서 분석해본 경험이 있습니다. 이 과정에서 의료기술 연구가 실질적인 사회적 가치를 창출하기 위해 어떤 제도와 정책적 기반이 필요한지에 대해 고민하게 되었고, 이후 과학기술 R&D와 보건의료제도의 통합적 연계 구조에 주목하며 분석 역량을 확장해왔습니다. 이외에도 신의료기술평가제도에서 건강보험 적용까지 이어지는 정책 구조를 분석하며, 의료기술의 효과성 및 안전성 뿐만 아니라 정책적 우선순위와 사회적 수용성까지 고려하는 통합적 평가체계의 필요성을 느꼈습니다. 저는 이러한 문제의식과 경험을 바탕으로 보건의료기술의 기획부터 도입까지 기술의 전주기를 다루는 다양한 연구과제에 참여했습니다. 대표적으로 코로나19 대응 기술의 기획 방향과 R&D 자원 배분 전략을 분석했고, 질병관리청의 여성건강 R&D 중장기 전략 수립에 참여하여 문제해결형 연구 기획의 전 과정을 수행했습니다. 또한, 아시아인프라투자은행(AIIB)의 디지털헬스케어 투자 전략을 수립하는 연구과제와 KOICA에서 발주한 PDP 기반 백신 및 치료제 도입을 다룬 과제에서는 기술성과, 투자 안정성, 제도적 수용성 등 여러 요인들 간의 균형을 고려해 실행력 있는 전략안을 도출했습니다. 이 과정에서 다양한 이해관계자의 입장을 구조화하고 정책과 제도, 산업 및 기술 간 조정 구조를 설계하는 역량을 기를 수 있었습니다. 저는 이러한 역량을 바탕으로 한국보건산업진흥원이 수행하는 R&D기획과, 성과관리, 글로벌 연계사업에서 중추적 역할을 수행하고 싶습니다. 그중에서도 R&D기획과 기술 활용이 단절되지 않고, 국민 건강 증진과 과학기술 혁신이 조화롭게 실현될 수 있도록 기여하고 싶습니다. | JR5: 제가 이해하는 한국보건산업진흥원의 역할은 국내 산학연병의 보건의료 R&D를 지원함으로써 보건의료기술의 혁신을 추동하고 이를 통해 국민이 개발된 기술의 혜택을 누려 건강 수준과 삶의 질을 향상시키는 것입니다. 그리고 동시에 국내 보건의료산업이 바이오헬스 글로벌 시장에서 혁신을 선도할 수 있도록 산업 기반을 조성하는 역할도 함께 수행하고 있다고 생각합니다. 조직의 가치 측면에서 한국보건산업진흥원은 기업의 기술 개발 지원을 넘어, 지속가능하고 조화로운 보건의료R&D 생태계를 구축하는 것을 핵심으로 삼고 있다고 이해하고 있습니다. 저는 산학연병을 아우르는 복잡한 보건의료R&D 환경에서 각 주체 간의 협력과 균형이 이루어질 때 비로소 진정한 기술혁신이 가능하고 한국보건산업진흥원은 조직 간의 유기적인 연계를 설계하고 조정하는 핵심적인 역할을 수행한다고 생각합니다. 저는 이러한 조직적 가치를 실현하기 위해 다음의 세 가지 직업윤리를 실천하고자 합니다. 첫째는 책임감 있는 전문성과 실행력입니다. 보건의료 R&D 사업의 기획과 관리는 실제 정책과 제도, 산업의 흐름 속에서 실현 가능한 방향을 제시하고 조율하는 능력을 요구한다고 생각합니다. 저는 과학기술과 R&D 정책에 대한 기초 역량을 갖춘 이후, 보건의료기술이 여러 제도를 거쳐 보건의료 현장으로 연결되는 과정을 폭넓게 탐색해왔습니다. 이 과정에서 기술과 제도, 산업 환경을 함께 고려해 실현 가능한 방향으로 정책 대안을 설정하고 상황에 맞는 기획 안을 신속하고 정확하게 정리하는 역량을 키웠습니다. 복잡한 이해관계나 제약 조건이 많은 환경에서 문제의 핵심을 파악하고 실용적 대안을 추구하는 저의 업무 방식은 향후 직무 수행에서도 효과적으로 작용할 수 있을 것이라 생각합니다. 그리고 저는 변화하는 환경 속에서도 유연하게 대응하고, 맡은 바 결과에 책임지는 자세로, 조직에 기여할 수 있는 실무형 인재가 되고 싶습니다. 둘째, 협조성은 산학연병 주체들이 서로 다른 문화를 기반으로 협업하고 있는 보건의료 R&D 생태계가 작동하기 위해 요구되는 필수적인 태도라고 생각합니다. 저는 과학기술개발과 보건의료 R&D 정책 기획이 교차하는 다학제적 환경을 경험해왔고, 관련 분야의 연구 수행과 연구과제 참여를 통해 임상연구를 수행하는 의료인과도 협력해왔습니다. 이러한 경험을 통해 각 조직의 운영방식과 소통 문화를 직접‧간접적으로 체득하였고, 이질적인 조직 간의 원활한 소통을 도와주는 역할을 수행할 수 있습니다. 셋째, 책무성은 직군을 불문하고 조직의 구성원으로서 반드시 갖춰야 할 태도라고 생각합니다. 저는 주어진 업무를 성실하게 수행해왔고, 새로운 주제를 접했을 때에는 해당 분야의 전문성을 갖추기 위해 진취적인 태도로 업무에 임해왔습니다. 이러한 자세를 바탕으로 앞으로 새로운 과제나 업무를 맡더라도 신속하고 정확하게 적응해 나가며, 조직이 요구하는 수준 이상의 성과를 낼 수 있도록 책임감을 갖고 노력할 계획입니다. | JS5: 기술과 산업, 정책과 제도 간의 관점 차이로 인해 보건의료 R&D 사업을 기획하거나 전략화하는 과정에서 갈등은 자주 발생합니다. 특히 참여하는 이해관계자가 많을수록 각자의 우선순위와 목표가 엇갈리기 때문에, 보건의료 R&D나 산업 육성을 둘러싼 초기 논의가 교착 상태에 빠지는 경우도 많습니다. 저는 연구자로서 참여한 두 개의 국제협력 프로젝트에서 이러한 갈등을 직접 경험했고, 유사한 방식을 통해 문제를 해결한 경험이 있습니다. 첫 번째 과제는 아시아인프라투자은행(AIIB)이 발주한 디지털 헬스케어 투자 전략 과제였습니다. 이 과제에서는 디지털헬스케어기업과 국제금융기구라는 양측의 시각 차이가 갈등의 중심에 있었습니다. 기업의 입장에서는 사업의 수익성과 시장 확장의 가능성에 중요한 가치를 두었고, AIIB는 투자 안정성, 규제 리스크, 실행 가능성을 핵심 고려사항으로 설정했습니다. 양측은 우선운위 뿐만 아니라 의료기기나 산업을 접근하는 방식, 혹은 투자에 대한 성과를 창출할 수 있는 시간에 대한 감각도 달랐기에, 과제 초반에는 분석 방향을 설정하기 어려울 정도로 난관을 겪었습니다. 저는 이 문제를 해결하기 위해 각 입장의 시간축·리스크 요인을 분해하여 구조화했고, 단계별 투자경로를 제안하는 방식으로 문제를 접근했습니다. 또한 국내 기업을 중심으로 투자 국가의 규제 제도와 시장 진입 사례를 고려하여 전략 안을 설계함으로써, 산업 육성의 관점과 국제금융기구의 투자 안정성 기준을 동시에 만족시킬 수 있었습니다. 해당 전략안은 이후 AIIB 내부 투자 검토 안에 반영되었고, 관계자로부터 전략의 설득력이 높아졌다는 긍정적인 피드백을 받았습니다. 비슷한 갈등 구조는 KOICA가 발주한 PDP 방식으로 개발된 감염병 백신과 치료제 수급에 관한 과제에서도 반복되었습니다. 이 연구과제에서 저는 중저소득국가의 감염병 백신 및 치료제 수급 문제를 해결하기 위해 제약사, 국제기구, 국가 내 조달기구 등 다양한 이해당사자를 대상으로 면담을 수행했습니다. 하지만 각 주체별로 운영 논리와 전략 목표가 달라 초기 논의부터 의견 충돌이 발생했고 논의가 진전되는데 어려움을 겪었습니다. 저는 각 이해당사자의 우선순위와 요구사항을 체계적으로 정리했고, 반복되는 쟁점과 현실적인 대안들을 도출하는 데 집중했습니다. 논의의 흐름이 정리되면서 연구진 내부의 방향성도 명확해졌고, 최종보고서에 다양한 제약 조건을 고려한 전략 안이 담길 수 있었습니다. 두 과제를 관통한 갈등의 본질은 서로 다른 논리 구조와 우선순위 간의 충돌이라고 생각합니다. 저는 두 과제에서 각 주체의 입장을 체계적으로 정리하고, 갈등이 되었던 쟁점을 현실에서 실행 가능한 대안으로 전환시켜 문제를 해결했습니다. 그리고 이러한 경험은 복잡한 이해관계가 얽힌 보건의료 R&D 환경에서 기획력과 조정 역량을 발휘하는 실무형 인재로 성장하는 데 중요한 밑거름이 되었다고 생각합니다. 향후 보건산업진흥원에서 근무할 기회가 주어진다면, 이러한 역량을 바탕으로 갈등을 해결하고 실질적인 대안 마련하는데 기여하고 싶습니다. | JT5: 저는 기초과학과 기술혁신 분야의 연구 기반을 다지며 과학기술 R&D 체계에 대한 실무적 감각을 익혔고, 이후 보건의료 R&D 기획을 다룬 다양한 연구과제 경험을 통해 관련 정책적 감각을 함께 확장해왔습니다. 그리고 저는 과학기술-보건학의 경계를 넘나드는 경험이 한국보건산업진흥원이 추진하는 보건의료 R&D 사업의 기획과 관리 업무에 실질적으로 기여할 수 있는 기반이 될 것이라고 생각합니다. 우선 저는 과학기술 R&D 정책과 기술혁신에 대한 폭넓은 이해를 강점으로 가지고 있습니다. 알츠하이머 진단기술 개발을 다룬 연구를 수행하며, 연구개발과제 수행부터 개발된 의료기술의 시장 진입가능성의 평가에 이르기까지, 기술의 전주기를 파악할 수 있는 경험을 통해 보건의료기술 혁신의 실현가능성과 제약 요인을 다각도로 파악할 수 있었습니다. 이후 코로나19 대응 기술, 디지털헬스케어, 감염병 백신과 치료제, 여성건강 등 국내외 다양한 연구과제에 참여하며 보건의료 R&D 정책기획, 기술개발 및 사업화 가능성, 제도적 연계 등 요인을 복합적으로 사고할 수 있는 역량을 키워왔습니다. 이러한 경험은 제게 보건의료기술의 혁신과 산업화 가능성을 동시에 고려할 수 있는 시야를 제공해주었고, 이는 보건산업진흥원의 사업기획 및 과제평가 업무에서 실질적인 자산이 될 수 있을 것으로 기대합니다. 둘째, 다양한 이해관계자가 참여하는 과제를 통해 의견 차이를 좁히고, 실행 가능한 대안을 도출할 수 있는 기획 역량을 발전시켜 왔습니다. 일례로 아시아인프라투자은행(AIIB)의 디지털헬스케어 투자 전략 과제에서는 기업이 수익성과 기술 확장성을 중시한 반면, 국제금융기구는 투자 안정성과 규제 리스크를 우선적으로 고려했습니다. 이러한 견해 차이는 초기 분석 방향 설정에 어려움을 주었는데, 저는 양측의 시간축과 리스크 요인을 구조적으로 정리한 후, 단계별 전략을 설계하여 양측 모두가 수용할 수 있는 대안을 도출하였습니다. 마지막으로, 저는 실무에서 신속한 실행력과 문제 해결능력을 중요한 역량으로 여기고 있습니다. 다양한 관점에서 문제를 검토하되, 실행으로 옮길 수 있는 대안을 빠르게 정리하고 제안하는 역량이야말로 사업기획 실무에 반드시 요구되는 자질이라고 생각하기 때문입니다. 그동안 저는 여러 연구과제를 수행해오며, 정해진 일정을 지키면서도 결과물의 질을 충족시키기 위해 주도적이고 능동적인 자세로 업무에 임해왔습니다. 이러한 역량은 실무에서도 체계적이면서도 신속하게 기획안을 수립하고 성과를 도출하는 데 기여할 수 있을 것이라고 생각합니다. 다만 제가 생각하는 저의 보완점은 역할 분담이 불분명한 공동 업무를 수행할 시, 업무의 공백을 줄이기 위해 과업을 주도적으로 떠맡는 경향이 있다는 점입니다. 책임감 있게 업무를 수행해나가려는 의도였지만, 경우에 따라 협업의 균형을 해칠 수도 있다는 점을 인식하게 되었습니다. 이에 최근에는 협업 초기 단계에서 구성원 간 역할과 책임을 명확히 조율하고, 팀원 간 진행 상황을 상시 공유함으로써 효율적인 협업을 실천하기 위해 노력하고 있습니다.
A6: 0005-000057 | B6: 윤두경 | C6: 1지망 : 국제의료사업지원-정규직(전임)-전문직/연구원-오송 | D6: 04_국제의료사업지원-정규직(전임)-전문직/연구원-오송 | E6: 1 | F6: 2025.07.18 | G6: 제출완료 | H6: 2025.07.24 | I6: Yoon Dookyoung | J6: cowydgy@naver.com | K6: 010-9780-5025 | L6: 010-6575-5025 | M6: 해당없음 | N6: 해당없음 | O6: 군필 | P6: 2010.04 | Q6: 2012.02 | R6: 만기제대 | S6: 병장 | T6: - | U6: - | V6: - | W6: - | X6: - | Y6: - | Z6: - | AA6: - | AB6: - | AC6: - | AD6: - | AE6: - | AF6: - | AG6: - | AH6: - | AI6: - | AJ6: - | AK6: - | AL6: - | AM6: - | AN6: - | AO6: - | AP6: - | AQ6: - | AR6: - | AS6: - | AT6: - | AU6: 6년7개월 | AV6: 정규직 | AW6: 대전광역시 공공보건의료지원단 | AX6: 3년8개월 | AY6: 2021.12.01 | AZ6: 재직중 | BA6: 의료정책연구팀 | BB6: 연구원 | BC6: 공공병원/보건소 대상 법정계획 수립에 관한 기술지원, 시민대상 타운홀 미팅, 홍보(카드뉴스 제작 및 서포터즈 운영) | BD6: 재직중 | BE6: 정규직 | BF6: 전국지속가능발전협의회 | BG6: 2년11개월 | BH6: 2019.01.01 | BI6: 2021.11.30 | BJ6: 사무총국 | BK6: 간사 | BL6: 대한민국 지속가능발전대회 기획 및 운영, 지속가능발전대상 공모전 운영, 대한민국 솔라리그 운영, 각종 위원회 대응, 지속가능발전 법 이슈 대응 등 | BM6: 개인사유 | BN6: - | BO6: - | BP6: - | BQ6: - | BR6: - | BS6: - | BT6: - | BU6: - | BV6: - | BW6: - | BX6: - | BY6: - | BZ6: - | CA6: - | CB6: - | CC6: - | CD6: - | CE6: - | CF6: - | CG6: - | CH6: - | CI6: - | CJ6: - | CK6: - | CL6: - | CM6: - | CN6: - | CO6: - | CP6: - | CQ6: - | CR6: - | CS6: - | CT6: - | CU6: - | CV6: - | CW6: - | CX6: - | CY6: - | CZ6: - | DA6: - | DB6: - | DC6: - | DD6: - | DE6: - | DF6: - | DG6: - | DH6: - | DI6: - | DJ6: - | DK6: - | DL6: - | DM6: - | DN6: - | DO6: - | DP6: - | DQ6: - | DR6: - | DS6: - | DT6: - | DU6: - | DV6: - | DW6: - | DX6: - | DY6: OPIc(영어) | DZ6: Intermediate Mid 3 | EA6: 2025.04.05 | EB6: 2H4899100502 | EC6: - | ED6: - | EE6: - | EF6: - | EG6: - | EH6: - | EI6: - | EJ6: - | EK6: - | EL6: - | EM6: - | EN6: - | EO6: - | EP6: - | EQ6: - | ER6: - | ES6: - | ET6: - | EU6: - | EV6: - | EW6: - | EX6: - | EY6: - | EZ6: - | FA6: - | FB6: - | FC6: - | FD6: - | FE6: - | FF6: - | FG6: - | FH6: - | FI6: - | FJ6: - | FK6: - | FL6: - | FM6: - | FN6: - | FO6: - | FP6: - | FQ6: - | FR6: 국제의료사업지원 - 7학점 | FS6: 공공마케팅 | FT6: 국제의료사업지원 | FU6: - | FV6: - | FW6: - | FX6: 정책 대상지 수요 파악 및 정책수립에 맞는 결과물 도출, 마케팅 관리 기본 프로세스 이해 등 | FY6: 1 | FZ6: - | GA6: - | GB6: 데이터 문해력 | GC6: 국제의료사업지원 | GD6: - | GE6: - | GF6: - | GG6: 각종 데이터 해석 및 분석, 통계적 사고를 통한 사실 확인 및 분석 | GH6: 1 | GI6: - | GJ6: - | GK6: 협상역량강화 | GL6: 국제의료사업지원 | GM6: - | GN6: - | GO6: - | GP6: 양자간 단일 의제 협상, 다자간 복수의제 협상 등 모의 협상 상황을 통한 갈등 상황 조정 | GQ6: 1 | GR6: - | GS6: - | GT6: Strategic Management | GU6: 국제의료사업지원 | GV6: - | GW6: - | GX6: - | GY6: 사업 또는 기관 분석을 위한 프레임워크 학습, 학습한 프레임워크를 통한 실제 기관 분석 등 | GZ6: 3 | HA6: - | HB6: - | HC6: Results-based Management and International Development Cooperation | HD6: 국제의료사업지원 | HE6: - | HF6: - | HG6: - | HH6: 국제개발협력분야에 대한 성과관리 정책 이론 및 실무기술 학습, 비용편익 분석과 비용효과성 분석, 성과평가 방법론, 기존의 성과평가보고서 비판 검토 | HI6: 1 | HJ6: - | HK6: - | HL6: - | HM6: - | HN6: - | HO6: - | HP6: - | HQ6: - | HR6: - | HS6: - | HT6: - | HU6: - | HV6: - | HW6: - | HX6: - | HY6: - | HZ6: - | IA6: - | IB6: - | IC6: - | ID6: - | IE6: - | IF6: - | IG6: - | IH6: - | II6: - | IJ6: - | IK6: - | IL6: - | IM6: - | IN6: - | IO6: - | IP6: - | IQ6: - | IR6: - | IS6: - | IT6: - | IU6: - | IV6: - | IW6: - | IX6: - | IY6: - | IZ6: - | JA6: - | JB6: 1498 | JC6: 1217 | JD6: 1094 | JE6: 1077 | JF6: 0124 | JG6: 비해당 | JH6: 비해당 | JI6: 비해당 | JJ6: 비해당 | JK6: 비해당 | JL6: 해당(대전) | JM6: 해당(대전) | JN6: 비해당 | JO6: 비해당 | JP6: 비해당 | JQ6: [데이터로 길을 찾고, 소통으로 성공할 글로벌 헬스케어 담당자] 한국보건산업진흥원의 국제의료사업은 단순한 행정지원을 넘어 대한민국의 미래 성장 동력인 보건사업의 해외진출을 돕기위한 핵심 직무라고 이해하고 있습니다. 특히 「제2차 의료 해외진출 및 외국인환자 유치 지원 종합계획」의 지향점인 양적 성장을 넘어 질적성장으로의 전환의 시기에서 중증·복합성 질환 유치를 확대하고 디지털 헬스케어와 같은 고부가가치 산업과의 융합을 통해 해외진출을 선도해야하는 전략적 과업을 가지고 있다고 생각합니다. 국제의료사업지원 직무는 두 가지 핵심역량을 요구한다고 생각합니다. 첫 번째로 “데이터기반의 정책/사업 기획 역량”입니다. 국제의료 시장의 방대한 데이터를 분석하고 변화의 흐름을 파악한 후, 국가 정책과 연계된 실효성있는 사업을 기획하는 능력입니다. 두 번째로 “글로벌 협업을 이끄는 사업관리 및 실행 역량”입니다. 다양한 이해관계자들과 신뢰를 구축하고 G2G 협력과 같은 대형 프로젝트를 성공적으로 완수할 수 있어야 합니다. 현재 재직중인 공공보건의료지원단에서는 공공병원읜 “공공보건의료계획 시행결과” 기술지원을 담당했습니다. 이 법정결과는 등급으로 공개되어 병원 담당자들에게는 예민한 내용부분이였으나 기존의 기술지원 방식이 피드백을 별도양식으로 제공하여 담당자들이 내용을 이해하는데 어려움을 겪었고 이는 잦은 유선문의와 수정 시간 지연으로 이어져 불필요한 행정력 낭비를 유발했습니다. 저는 점수 향상을 넘어, 기술지원을 신뢰 기반의 협력과정으로 전환하는 것을 목표로 삼고 진정한 파트너가 되고자 두 가지 혁신을 주도했습니다. 첫 번째, 찾아가는 피드백 별도양식의 기술지원을 넘어 각 병원의 시행결과 초안 파일에 메모와 추가의견을 달아 수정방향을 제시하고, 담당자가 직관적으로 내용을 파악하고 개선할수 있게했습니다. 두 번째, 선제적 대응 병원들이 가장 어려워 하는 사업의 근거 제시 문제를 해결하기 위해 각 병원의 사업과 관련된 상위 법정계획과 최신 통계데이터를 파악하고 기술지원시 00번 사업의 경우 00법정계획의 0번 전략과 일치함으로 해당 자료를 사용하여 근거를 강화하시죠. 와 같은 구체적인 가이드를 제공하였습니다. 한해의 결과로 병원들의 결과가 극적으로 상향되진 않았지만. 저는 두가지의 정성적 성과를 얻어내었습니다. 1. 측정가능한 업무효율 담당자로부터 몇 달씩 걸리던 시행결과 작성이 덕분에 더 빠르게 잘 끝날 수 있었다라는 감사인사를 받았고 기술지원이 실제 공공병원담당자의 업무부담 감소로 이어지게 하였습니다. 2. 지속가능한 신뢰관계 구축 올해의 마지막 기술지원에서 한 병원의 담당자께서는 ‘선생님 덕분에 시행결과를 작성하면서 혼자 쓰는 것이 아닌 함께하는 느낌을 받았습니다’라는 말을 들을수 있었습니다. 방어적이던 관계에서 신뢰와 협력의 관계로 전환된것입니다. 이 과정을 통해 신뢰에 기반한 과정의 혁신이 파트너의 성공을 이끌어내는 원동력임을 배웠고, 진흥원의 다양한 파트너들과 협력하고 효율적인 프로세스를 설계하여 상생의 생태계를 만들고 싶습니다. | JR6: [혁신을 위한 배움, 신뢰를 위한 소통] 제가 이해하는 한국보건산업진흥원은 대한민국 보건산업의 미래를 열어가는 '코칭플레이어'입니다. 이 역할을 성공적으로 수행하기 위해선, 현실에 안주하지 않고 더 나은 방식을 찾아내는 ‘혁신을 위한 배움’과, 다양한 참여자의 목소리를 동등하게 존중하는 ‘신뢰 기반의 소통과 협력’ 이라는 두 가지 가치가 무엇보다 중요하다고 생각합니다. 저는 이러한 가치를 다음과 같은 경험을 통해 실천해왔습니다. 첫째, ‘혁신을 위한 배움’을 실천하여 결과물의 가치를 높였습니다. ‘대전 시민 원탁회의’ 운영을 맡았을 때, 타운홀 미팅이 일회성 행사로 끝나는 한계를 넘고 싶었습니다. 단순한 의견 수렴을 넘어, 지자체가 실제 사업에 반영할 수 있는 '정책 제안서' 수준의 결과물을 만드는 것이 목표였습니다. 이를 위해, 당시 대학원에서 학습하던 정책 성과평가 이론을 실무에 적용했습니다. 시민들의 제안이 어떤 정책 목표와 연결되고, 어떤 기대효과를 낳을 수 있는지 분석하는 새로운 보고서 양식을 직접 설계하여 원탁회의 결과 보고서에 첨부했습니다. 그 결과, 단순 행사였던 원탁회의를 '정책화가 가능한 제안'을 생산하는 구조로 발전시켰다는 점에서 담당 공무원에게 높은 평가를 받았습니다. 이는 현실의 문제를 해결하기 위해 끊임없이 배우고, 배운 것을 적용해 더 나은 방식을 만들어내는 저의 강점을 보여주는 경험입니다. 둘째, ‘신뢰 기반의 소통’으로 모두의 참여를 이끌어냈습니다. 원탁회의의 주제인 보건의료 정책은 공급자 중심으로 논의되어 시민들이 의견을 내기 어려운 대표적인 분야입니다. 저는 이 정보 비대칭을 해소하고, 시민들이 논의의 동등한 주체로 참여할 수 있는 신뢰의 장을 만드는 것을 중요하게 생각했습니다. 이를 위해, 어려운 전문 용어를 쉬운 말로 풀어쓴 사전 교육자료를 배포하고, 행사 당일에도 눈높이에 맞춘 교육 세션을 진행했습니다. 이러한 노력 덕분에, 시민들은 수동적인 수혜자가 아닌 논의의 적극적인 주체로 참여할 수 있었고, 이전보다 훨씬 구체적이고 현실적인 아이디어를 제시했습니다. 이는 모든 참여자를 존중하고 투명한 소통으로 신뢰를 얻을 때, 가장 큰 협력의 시너지가 나온다는 것을 깨닫게 한 경험이었습니다. 배움을 통해 더 나은 결과물을 만들고, 소통을 통해 파트너의 참여를 이끌어내는 저의 역량은, 국내외 다양한 이해관계자들과 협력하여 K-헬스케어의 미래를 열어야 하는 진흥원에서 핵심적인 역할을 수행할 것이라 확신합니다. | JS6: [문제해결의 퍼실리테이터] 2019년, 환경부와 지방정부, 시민사회가 함께하는 “대한민국 지속가능발전대회”의 운영 간사 역할을 맡았을 때, 10여개의 기관이 각자의 세션 운영을 위해 특정 시간과 장소를 선점하려는 문제에 직면하였습니다. 한정된 시간과 접근성이 좋은 장소에 대한 경쟁이 심화되면서 모두의 지속가능발전이라는 행사의 취지가 퇴색되고 참여기관들의 만족도가 떨어질것으로 예상되는 상황이였습니다. 저는 목표는 단순한 시간표와 장소배정을 넘어 모든 참여기관이 최대한 만족하고 납득할수 있는 합리적 해결책을 도출하고 싶었고 이를 통해 행사의 질을 높이고 지속적인 협력의 기반을 다지고 싶었습니다. 저는 문제의 본질이 정보의 비대칭성에서 있다고 진단하여 문제해결을 위해 세단계를 거쳤습니다. 1. 투명한 정보시스템 구축, 모든 기관의 요구사항(시간, 장소, 필요기자재)를 모두가 볼수 있는 구글시트를 제작하여 링크를 공유하고 ‘공동의 문제’로 인식시켰습니다. 2. 합리적인 우선순위 구축. 내 조건의 만족이 다른 기관의 세션운영에 제한을 줄수 있다는 상황을 인지시킨후 각 기관에 반드시 충족되어야할 1순위·2순위 조건을 시트에 직접 표시하여 나만의 최선이 아닌 모두가 상생할수 있는 타협가능한 최선을 고민하게 했습니다. 3. 의사결정 과정. 취합된 우선순위를 바탕으로 중복되는 기관의 담당자들을 대상으로 온라인 회의를 주재하여 각 기관의 우선순위를 보고 의견을 조율하였고 같이 데이터에 기반한 논의를 이끌었습니다. 일방적 통보가 아닌 객관적인 정보를 바탕으로한 설득을 통해 모두가 수긍하는 결론을 이끌어낼수 있었습니다. 그 결과, 총 10개의 세션이 성공적으로 마칠 수 있었고, 행사 종료후 설문조사에서도 기관만족도 4.3점/5점, 참가자 만족도 4.5점/5점이라는 정량적 성과를 달성할수 있었습니다. 이 과정에서 쌓인 신뢰를 통해 2021년 하이브리드로 진행된 대한민국 지속가능발전대회에도 유관기관들이 적극적으로 참여하는 장기적 협력관계를 구축할 수 있었습니다. 이 경험에서 저는 문제해결을 위해 퍼실리테이로써 갈등 상황(문제)에서 정답을 제시하는것도 좋지만 모두가 신뢰할 수 있는 절차를 만들고 참여자들이 스스로 해답을 찾게 할 수 있었습니다. | JT6: [다양한 이해관계자와의 협업 및 조정능력] 저는 서로 다른 입장과 목표를 가진 주체를 사이에서 공동의 목표를 설정하고, 원활환 소통과 협상을 통해 최적의 결과물을 도출하는 데 강점이 있습니다. 이는 과거 여러 기관과 이해관계자들의 요구사항을 성공적으로 조율하고 프로젝트를 완수한 경험에서 생겨났습니다. 이 강점은 “국제 의료사업 지원” 직무에서 크게 발휘될 거로 생각합니다. 진흥원은 보건복지부의 전략적 파트너이고 실행 기구입니다. 국가의 정책을 현장에서 사업으로 전환하는 데 중요한 역할을 맡고 있고 이 과정은 이해관계자(중앙부처, 연구계, 산업계 등)와의 협상 및 커뮤니케이션 기술을 필수적으로 요구한다고 믿고 있습니다. 특히 2차 의료 해외 진출 및 외국인 환자 유치지원 종합계획에 따른 산업 융합형 신시장 창출 전략은 의료분야 하나를 넘어 의료-관광-제약-의료기기 등 연관 산업의 동반 진출을 지원하고 있기에 다양한 주체들과의 의견조율이 필요하다고 생각합니다. 진흥원이 구성원들과의 정보·업무·책임·의사결정 등을 적극적으로 수렴하고 공유하는 태도를 강조하는 조직문화 또한 저의 강점이 발휘될 수 있는 환경입니다. 입사 후에는 협업과 조정 능력의 강점을 발휘하여 복합적인 국제 의료사업 프로젝트에서 모두가 만족할 수 있는 결과를 이끌어 내고, 진흥원의 리더십 강화에 기여하겠습니다. 반면 제가 보완해야 하는 약점은 “다양한 보건사업 연관 분야에 대한 실무경험 부족”입니다, 저는 주로 지속 가능한 발전·공공보건의료에 집중해서 경력을 쌓았으니 진흥원 업무는 제약·바이오·의료기기·미용·한방 등 광범위한 분야의 해외 진출을 지원하고 있기에 산업별 특성과 규제 이해가 필요합니다. 이는 다양한 이해관계자들과의 협상 시에는 지식의 범위가 부족할 수 있다는 한계가 예상됩니다. 이런 약점을 보완하기 위해 진흥원의 ‘조직문화’와 ‘업무환경’을 적극 활용하려고 합니다. 진흥원은 전문 분야별 맞춤형 교육체계를 운영하고 있어 전문 지식 습득을 위한 환경이 잘 조정되어 있고 저는 끊임없이 배우려는 자세로 계속해서 새로운 산업과 법에 대한 지식을 키워나감으로 정책을 기반으로 한 사업 개발 전문가로서의 역량을 키워나가려 합니다.
